Workbook

Sheet Portada
B4: S E G U I M I E N T O P E R S O N A L
B6: Hábitos
B9: Doce meses, una marca por día, cero adivinanzas
B11: Jesús González · https://jesus-site-silk.vercel.app/
B15: CÓMO ESTÁ ORGANIZADO
B16: Resumen | C16: El mes en curso, con días cumplidos y porcentaje de logro.
B17: Mis Hábitos | C17: Define aquí qué vas a seguir. Empieza por esta hoja.
B18: Enero … Diciembre | C18: Una hoja por mes con la cuadrícula de días. Aquí marcas.
B19: Año | C19: Los doce meses lado a lado y el espacio de revisión mensual.
B20: Listas | C20: Catálogos de áreas, frecuencias y momentos del día.
B22: CÓMO SE MARCA
B23: x | C23: Cumpliste. La celda se pone verde.
B24: - | C24: Ese día no aplicaba (viaje, enfermedad, día de descanso planeado). No cuenta en contra.
B25: vacío | C25: No se cumplió. Sin drama: la casilla vacía es información, no un reproche.
B27: CUATRO IDEAS QUE HACEN QUE ESTO FUNCIONE
B28: Empieza ridículamente pequeño | C28: «Diez páginas» en lugar de «leer más». Un hábito que puedes cumplir en un mal día es un hábito que sobrevive. Siempre puedes hacer de más; no siempre puedes empezar.
B29: Engánchalo a algo que ya haces | C29: La columna de detonante existe por eso. «Después de servirme el café» funciona mejor que «a las 7:00», porque el café ya está en tu día y la hora no.
B30: Nunca falles dos veces seguidas | C30: Un día perdido es un accidente; dos son el inicio de otro hábito. La racha no es el objetivo, pero volver al día siguiente sí lo es.
B31: Cinco hábitos, no doce | C31: Hay doce filas porque a lo largo del año algunos entran y otros salen. Llevar doce al mismo tiempo es la forma más confiable de abandonar todos en marzo.
B33: El porcentaje de logro es información para ajustar, no una calificación. Un 70% sostenido durante un año supera a un 100% que dura tres semanas.
B35: Jesús González · https://jesus-site-silk.vercel.app/

Sheet Resumen
A1: RESUMEN DEL MES EN CURSO
A2: Cambia el mes en la celda amarilla y todos los indicadores se recalculan.
A3: Jesús González · https://jesus-site-silk.vercel.app/
B6: Mes que quiero ver: | C6: Julio
B10: PANORAMA
B12: HÁBITOS DEFINIDOS | E12: ACTIVOS | H12: EN PAUSA
B13: =COUNTIF('Mis Hábitos'!$B$7:$B$18,"?*") -> 4 | E13: =COUNTIF('Mis Hábitos'!$I$7:$I$18,"Activo") -> 4 | H13: =COUNTIF('Mis Hábitos'!$I$7:$I$18,"En pausa") -> 0
B16: DETALLE DEL MES SELECCIONADO
B17: Hábito | C17: Días cumplidos | D17: Meta del mes | E17: % Logro
B18: ='Mis Hábitos'!$B$7 -> Leer 10 páginas | C18: =IF($B18="","",INDEX(Año!$C$7:$N$7,MATCH($C$6,Listas!$E$7:$E$18,0))) -> 0 | D18: =IF(OR($B18="",'Mis Hábitos'!$F$7=""),"",ROUND('Mis Hábitos'!$F$7*DAY(EOMONTH(DATE(2026,MATCH($C$6,Listas!$E$7:$E$18,0),1),0))/7,0)) -> 31 | E18: =IF(OR($B18="",$D18="",$D18=0),"",$C18/$D18) -> 0
B19: ='Mis Hábitos'!$B$8 -> Caminar 30 minutos | C19: =IF($B19="","",INDEX(Año!$C$8:$N$8,MATCH($C$6,Listas!$E$7:$E$18,0))) -> 0 | D19: =IF(OR($B19="",'Mis Hábitos'!$F$8=""),"",ROUND('Mis Hábitos'!$F$8*DAY(EOMONTH(DATE(2026,MATCH($C$6,Listas!$E$7:$E$18,0),1),0))/7,0)) -> 22 | E19: =IF(OR($B19="",$D19="",$D19=0),"",$C19/$D19) -> 0
B20: ='Mis Hábitos'!$B$9 -> Revisar pendientes de la semana | C20: =IF($B20="","",INDEX(Año!$C$9:$N$9,MATCH($C$6,Listas!$E$7:$E$18,0))) -> 0 | D20: =IF(OR($B20="",'Mis Hábitos'!$F$9=""),"",ROUND('Mis Hábitos'!$F$9*DAY(EOMONTH(DATE(2026,MATCH($C$6,Listas!$E$7:$E$18,0),1),0))/7,0)) -> 4 | E20: =IF(OR($B20="",$D20="",$D20=0),"",$C20/$D20) -> 0
B21: ='Mis Hábitos'!$B$10 -> Practicar guitarra 15 minutos | C21: =IF($B21="","",INDEX(Año!$C$10:$N$10,MATCH($C$6,Listas!$E$7:$E$18,0))) -> 0 | D21: =IF(OR($B21="",'Mis Hábitos'!$F$10=""),"",ROUND('Mis Hábitos'!$F$10*DAY(EOMONTH(DATE(2026,MATCH($C$6,Listas!$E$7:$E$18,0),1),0))/7,0)) -> 13 | E21: =IF(OR($B21="",$D21="",$D21=0),"",$C21/$D21) -> 0
B22: ='Mis Hábitos'!$B$11 -> 0 | C22: =IF($B22="","",INDEX(Año!$C$11:$N$11,MATCH($C$6,Listas!$E$7:$E$18,0))) | D22: =IF(OR($B22="",'Mis Hábitos'!$F$11=""),"",ROUND('Mis Hábitos'!$F$11*DAY(EOMONTH(DATE(2026,MATCH($C$6,Listas!$E$7:$E$18,0),1),0))/7,0)) | E22: =IF(OR($B22="",$D22="",$D22=0),"",$C22/$D22)
B23: ='Mis Hábitos'!$B$12 -> 0 | C23: =IF($B23="","",INDEX(Año!$C$12:$N$12,MATCH($C$6,Listas!$E$7:$E$18,0))) | D23: =IF(OR($B23="",'Mis Hábitos'!$F$12=""),"",ROUND('Mis Hábitos'!$F$12*DAY(EOMONTH(DATE(2026,MATCH($C$6,Listas!$E$7:$E$18,0),1),0))/7,0)) | E23: =IF(OR($B23="",$D23="",$D23=0),"",$C23/$D23)
B24: ='Mis Hábitos'!$B$13 -> 0 | C24: =IF($B24="","",INDEX(Año!$C$13:$N$13,MATCH($C$6,Listas!$E$7:$E$18,0))) | D24: =IF(OR($B24="",'Mis Hábitos'!$F$13=""),"",ROUND('Mis Hábitos'!$F$13*DAY(EOMONTH(DATE(2026,MATCH($C$6,Listas!$E$7:$E$18,0),1),0))/7,0)) | E24: =IF(OR($B24="",$D24="",$D24=0),"",$C24/$D24)
B25: ='Mis Hábitos'!$B$14 -> 0 | C25: =IF($B25="","",INDEX(Año!$C$14:$N$14,MATCH($C$6,Listas!$E$7:$E$18,0))) | D25: =IF(OR($B25="",'Mis Hábitos'!$F$14=""),"",ROUND('Mis Hábitos'!$F$14*DAY(EOMONTH(DATE(2026,MATCH($C$6,Listas!$E$7:$E$18,0),1),0))/7,0)) | E25: =IF(OR($B25="",$D25="",$D25=0),"",$C25/$D25)
B26: ='Mis Hábitos'!$B$15 -> 0 | C26: =IF($B26="","",INDEX(Año!$C$15:$N$15,MATCH($C$6,Listas!$E$7:$E$18,0))) | D26: =IF(OR($B26="",'Mis Hábitos'!$F$15=""),"",ROUND('Mis Hábitos'!$F$15*DAY(EOMONTH(DATE(2026,MATCH($C$6,Listas!$E$7:$E$18,0),1),0))/7,0)) | E26: =IF(OR($B26="",$D26="",$D26=0),"",$C26/$D26)
B27: ='Mis Hábitos'!$B$16 -> 0 | C27: =IF($B27="","",INDEX(Año!$C$16:$N$16,MATCH($C$6,Listas!$E$7:$E$18,0))) | D27: =IF(OR($B27="",'Mis Hábitos'!$F$16=""),"",ROUND('Mis Hábitos'!$F$16*DAY(EOMONTH(DATE(2026,MATCH($C$6,Listas!$E$7:$E$18,0),1),0))/7,0)) | E27: =IF(OR($B27="",$D27="",$D27=0),"",$C27/$D27)
B28: ='Mis Hábitos'!$B$17 -> 0 | C28: =IF($B28="","",INDEX(Año!$C$17:$N$17,MATCH($C$6,Listas!$E$7:$E$18,0))) | D28: =IF(OR($B28="",'Mis Hábitos'!$F$17=""),"",ROUND('Mis Hábitos'!$F$17*DAY(EOMONTH(DATE(2026,MATCH($C$6,Listas!$E$7:$E$18,0),1),0))/7,0)) | E28: =IF(OR($B28="",$D28="",$D28=0),"",$C28/$D28)
B29: ='Mis Hábitos'!$B$18 -> 0 | C29: =IF($B29="","",INDEX(Año!$C$18:$N$18,MATCH($C$6,Listas!$E$7:$E$18,0))) | D29: =IF(OR($B29="",'Mis Hábitos'!$F$18=""),"",ROUND('Mis Hábitos'!$F$18*DAY(EOMONTH(DATE(2026,MATCH($C$6,Listas!$E$7:$E$18,0),1),0))/7,0)) | E29: =IF(OR($B29="",$D29="",$D29=0),"",$C29/$D29)
B31: La racha máxima de cada hábito se ve en la hoja del mes correspondiente.
B33: Jesús González · https://jesus-site-silk.vercel.app/

Sheet Mis Hábitos
A1: MIS HÁBITOS
A2: Define aquí qué vas a seguir. Los nombres se copian solos a las hojas de cada mes.
A3: Jesús González · https://jesus-site-silk.vercel.app/
A6: # | B6: Hábito | C6: Área | D6: Frecuencia | E6: Momento | F6: Meta semanal | G6: Detonante (después de…) | H6: Por qué me importa | I6: Estado
A7: =IF($B7="","",ROW()-6) -> 1 | B7: Leer 10 páginas | C7: Aprendizaje | D7: Todos los días | E7: Noche | F7: =IF($B7="","",IF($D7="Todos los días",7,IF($D7="Días hábiles",5,IF($D7="5 por semana",5,IF($D7="3 por semana",3,IF($D7="2 por semana",2,IF($D7="1 por semana",1,""))))))) -> 7 | G7: después de cenar | H7: Quiero terminar 12 libros este año | I7: Activo
A8: =IF($B8="","",ROW()-6) -> 2 | B8: Caminar 30 minutos | C8: Salud | D8: 5 por semana | E8: Mañana | F8: =IF($B8="","",IF($D8="Todos los días",7,IF($D8="Días hábiles",5,IF($D8="5 por semana",5,IF($D8="3 por semana",3,IF($D8="2 por semana",2,IF($D8="1 por semana",1,""))))))) -> 5 | G8: después de dejar a los niños | H8: Me despeja la cabeza antes de trabajar | I8: Activo
A9: =IF($B9="","",ROW()-6) -> 3 | B9: Revisar pendientes de la semana | C9: Trabajo | D9: 1 por semana | E9: Tarde | F9: =IF($B9="","",IF($D9="Todos los días",7,IF($D9="Días hábiles",5,IF($D9="5 por semana",5,IF($D9="3 por semana",3,IF($D9="2 por semana",2,IF($D9="1 por semana",1,""))))))) -> 1 | G9: después de la comida del viernes | H9: Empezar el lunes sin caos | I9: Activo
A10: =IF($B10="","",ROW()-6) -> 4 | B10: Practicar guitarra 15 minutos | C10: Creatividad | D10: 3 por semana | E10: Noche | F10: =IF($B10="","",IF($D10="Todos los días",7,IF($D10="Días hábiles",5,IF($D10="5 por semana",5,IF($D10="3 por semana",3,IF($D10="2 por semana",2,IF($D10="1 por semana",1,""))))))) -> 3 | G10: después de guardar la computadora | H10: Es lo único que hago solo por gusto | I10: Activo
A11: =IF($B11="","",ROW()-6) | F11: =IF($B11="","",IF($D11="Todos los días",7,IF($D11="Días hábiles",5,IF($D11="5 por semana",5,IF($D11="3 por semana",3,IF($D11="2 por semana",2,IF($D11="1 por semana",1,"")))))))
A12: =IF($B12="","",ROW()-6) | F12: =IF($B12="","",IF($D12="Todos los días",7,IF($D12="Días hábiles",5,IF($D12="5 por semana",5,IF($D12="3 por semana",3,IF($D12="2 por semana",2,IF($D12="1 por semana",1,"")))))))
A13: =IF($B13="","",ROW()-6) | F13: =IF($B13="","",IF($D13="Todos los días",7,IF($D13="Días hábiles",5,IF($D13="5 por semana",5,IF($D13="3 por semana",3,IF($D13="2 por semana",2,IF($D13="1 por semana",1,"")))))))
A14: =IF($B14="","",ROW()-6) | F14: =IF($B14="","",IF($D14="Todos los días",7,IF($D14="Días hábiles",5,IF($D14="5 por semana",5,IF($D14="3 por semana",3,IF($D14="2 por semana",2,IF($D14="1 por semana",1,"")))))))
A15: =IF($B15="","",ROW()-6) | F15: =IF($B15="","",IF($D15="Todos los días",7,IF($D15="Días hábiles",5,IF($D15="5 por semana",5,IF($D15="3 por semana",3,IF($D15="2 por semana",2,IF($D15="1 por semana",1,"")))))))
A16: =IF($B16="","",ROW()-6) | F16: =IF($B16="","",IF($D16="Todos los días",7,IF($D16="Días hábiles",5,IF($D16="5 por semana",5,IF($D16="3 por semana",3,IF($D16="2 por semana",2,IF($D16="1 por semana",1,"")))))))
A17: =IF($B17="","",ROW()-6) | F17: =IF($B17="","",IF($D17="Todos los días",7,IF($D17="Días hábiles",5,IF($D17="5 por semana",5,IF($D17="3 por semana",3,IF($D17="2 por semana",2,IF($D17="1 por semana",1,"")))))))
A18: =IF($B18="","",ROW()-6) | F18: =IF($B18="","",IF($D18="Todos los días",7,IF($D18="Días hábiles",5,IF($D18="5 por semana",5,IF($D18="3 por semana",3,IF($D18="2 por semana",2,IF($D18="1 por semana",1,"")))))))
B20: Menos es más: cinco hábitos que sostienes valen más que doce que abandonas en marzo.
A22: Jesús González · https://jesus-site-silk.vercel.app/

Sheet Enero
A1: ENERO 2026
A2: Marca con una X cada día que cumpliste. Todo lo demás se calcula solo.
A3: Jesús González · https://jesus-site-silk.vercel.app/
D5: J | E5: V | F5: S | G5: D | H5: L | I5: M | J5: M | K5: J | L5: V | M5: S | N5: D | O5: L | P5: M | Q5: M | R5: J | S5: V | T5: S | U5: D | V5: L | W5: M | X5: M | Y5: J | Z5: V | AA5: S | AB5: D | AC5: L | AD5: M | AE5: M | AF5: J | AG5: V | AH5: S
B6: Hábito | C6: Meta | D6: 1 | E6: 2 | F6: 3 | G6: 4 | H6: 5 | I6: 6 | J6: 7 | K6: 8 | L6: 9 | M6: 10 | N6: 11 | O6: 12 | P6: 13 | Q6: 14 | R6: 15 | S6: 16 | T6: 17 | U6: 18 | V6: 19 | W6: 20 | X6: 21 | Y6: 22 | Z6: 23 | AA6: 24 | AB6: 25 | AC6: 26 | AD6: 27 | AE6: 28 | AF6: 29 | AG6: 30 | AH6: 31 | AI6: Hechos | AJ6: Meta mes | AK6: % Logro | AL6: Racha máx.
B7: ='Mis Hábitos'!$B$7 -> Leer 10 páginas | C7: =IF('Mis Hábitos'!$B$7="","",'Mis Hábitos'!$F$7) -> 7 | AI7: =IF($B7="","",COUNTIF(D7:AH7,"x")) -> 0 | AJ7: =IF(OR($B7="",$C7=""),"",ROUND($C7*31/7,0)) -> 31 | AK7: =IF(OR($B7="",AJ7="",AJ7=0),"",AI7/AJ7) -> 0 | AL7: =IF($B7="","",MAX(D21:AH21)) -> 0
B8: ='Mis Hábitos'!$B$8 -> Caminar 30 minutos | C8: =IF('Mis Hábitos'!$B$8="","",'Mis Hábitos'!$F$8) -> 5 | AI8: =IF($B8="","",COUNTIF(D8:AH8,"x")) -> 0 | AJ8: =IF(OR($B8="",$C8=""),"",ROUND($C8*31/7,0)) -> 22 | AK8: =IF(OR($B8="",AJ8="",AJ8=0),"",AI8/AJ8) -> 0 | AL8: =IF($B8="","",MAX(D22:AH22)) -> 0
B9: ='Mis Hábitos'!$B$9 -> Revisar pendientes de la semana | C9: =IF('Mis Hábitos'!$B$9="","",'Mis Hábitos'!$F$9) -> 1 | AI9: =IF($B9="","",COUNTIF(D9:AH9,"x")) -> 0 | AJ9: =IF(OR($B9="",$C9=""),"",ROUND($C9*31/7,0)) -> 4 | AK9: =IF(OR($B9="",AJ9="",AJ9=0),"",AI9/AJ9) -> 0 | AL9: =IF($B9="","",MAX(D23:AH23)) -> 0
B10: ='Mis Hábitos'!$B$10 -> Practicar guitarra 15 minutos | C10: =IF('Mis Hábitos'!$B$10="","",'Mis Hábitos'!$F$10) -> 3 | AI10: =IF($B10="","",COUNTIF(D10:AH10,"x")) -> 0 | AJ10: =IF(OR($B10="",$C10=""),"",ROUND($C10*31/7,0)) -> 13 | AK10: =IF(OR($B10="",AJ10="",AJ10=0),"",AI10/AJ10) -> 0 | AL10: =IF($B10="","",MAX(D24:AH24)) -> 0
B11: ='Mis Hábitos'!$B$11 -> 0 | C11: =IF('Mis Hábitos'!$B$11="","",'Mis Hábitos'!$F$11) | AI11: =IF($B11="","",COUNTIF(D11:AH11,"x")) | AJ11: =IF(OR($B11="",$C11=""),"",ROUND($C11*31/7,0)) | AK11: =IF(OR($B11="",AJ11="",AJ11=0),"",AI11/AJ11) | AL11: =IF($B11="","",MAX(D25:AH25))
B12: ='Mis Hábitos'!$B$12 -> 0 | C12: =IF('Mis Hábitos'!$B$12="","",'Mis Hábitos'!$F$12) | AI12: =IF($B12="","",COUNTIF(D12:AH12,"x")) | AJ12: =IF(OR($B12="",$C12=""),"",ROUND($C12*31/7,0)) | AK12: =IF(OR($B12="",AJ12="",AJ12=0),"",AI12/AJ12) | AL12: =IF($B12="","",MAX(D26:AH26))
B13: ='Mis Hábitos'!$B$13 -> 0 | C13: =IF('Mis Hábitos'!$B$13="","",'Mis Hábitos'!$F$13) | AI13: =IF($B13="","",COUNTIF(D13:AH13,"x")) | AJ13: =IF(OR($B13="",$C13=""),"",ROUND($C13*31/7,0)) | AK13: =IF(OR($B13="",AJ13="",AJ13=0),"",AI13/AJ13) | AL13: =IF($B13="","",MAX(D27:AH27))
B14: ='Mis Hábitos'!$B$14 -> 0 | C14: =IF('Mis Hábitos'!$B$14="","",'Mis Hábitos'!$F$14) | AI14: =IF($B14="","",COUNTIF(D14:AH14,"x")) | AJ14: =IF(OR($B14="",$C14=""),"",ROUND($C14*31/7,0)) | AK14: =IF(OR($B14="",AJ14="",AJ14=0),"",AI14/AJ14) | AL14: =IF($B14="","",MAX(D28:AH28))
B15: ='Mis Hábitos'!$B$15 -> 0 | C15: =IF('Mis Hábitos'!$B$15="","",'Mis Hábitos'!$F$15) | AI15: =IF($B15="","",COUNTIF(D15:AH15,"x")) | AJ15: =IF(OR($B15="",$C15=""),"",ROUND($C15*31/7,0)) | AK15: =IF(OR($B15="",AJ15="",AJ15=0),"",AI15/AJ15) | AL15: =IF($B15="","",MAX(D29:AH29))
B16: ='Mis Hábitos'!$B$16 -> 0 | C16: =IF('Mis Hábitos'!$B$16="","",'Mis Hábitos'!$F$16) | AI16: =IF($B16="","",COUNTIF(D16:AH16,"x")) | AJ16: =IF(OR($B16="",$C16=""),"",ROUND($C16*31/7,0)) | AK16: =IF(OR($B16="",AJ16="",AJ16=0),"",AI16/AJ16) | AL16: =IF($B16="","",MAX(D30:AH30))
B17: ='Mis Hábitos'!$B$17 -> 0 | C17: =IF('Mis Hábitos'!$B$17="","",'Mis Hábitos'!$F$17) | AI17: =IF($B17="","",COUNTIF(D17:AH17,"x")) | AJ17: =IF(OR($B17="",$C17=""),"",ROUND($C17*31/7,0)) | AK17: =IF(OR($B17="",AJ17="",AJ17=0),"",AI17/AJ17) | AL17: =IF($B17="","",MAX(D31:AH31))
B18: ='Mis Hábitos'!$B$18 -> 0 | C18: =IF('Mis Hábitos'!$B$18="","",'Mis Hábitos'!$F$18) | AI18: =IF($B18="","",COUNTIF(D18:AH18,"x")) | AJ18: =IF(OR($B18="",$C18=""),"",ROUND($C18*31/7,0)) | AK18: =IF(OR($B18="",AJ18="",AJ18=0),"",AI18/AJ18) | AL18: =IF($B18="","",MAX(D32:AH32))
B19: Cumplidos del día | D19: =COUNTIF(D7:D18,"x") -> 0 | E19: =COUNTIF(E7:E18,"x") -> 0 | F19: =COUNTIF(F7:F18,"x") -> 0 | G19: =COUNTIF(G7:G18,"x") -> 0 | H19: =COUNTIF(H7:H18,"x") -> 0 | I19: =COUNTIF(I7:I18,"x") -> 0 | J19: =COUNTIF(J7:J18,"x") -> 0 | K19: =COUNTIF(K7:K18,"x") -> 0 | ... AH19: =COUNTIF(AH7:AH18,"x") -> 0
B20: x = cumplido · - = no aplicaba ese día · vacío = no se cumplió La columna del día de hoy aparece con borde naranja.
B21: =IF($B7="","",$B7) -> Leer 10 páginas | D21: =IF(D7="x",1,0) -> 0 | E21: =IF(E7="x",D21+1,0) -> 0 | F21: =IF(F7="x",E21+1,0) -> 0 | G21: =IF(G7="x",F21+1,0) -> 0 | H21: =IF(H7="x",G21+1,0) -> 0 | I21: =IF(I7="x",H21+1,0) -> 0 | J21: =IF(J7="x",I21+1,0) -> 0 | K21: =IF(K7="x",J21+1,0) -> 0 | L21: =IF(L7="x",K21+1,0) -> 0 | ... AH21: =IF(AH7="x",AG21+1,0) -> 0
B22: =IF($B8="","",$B8) -> Caminar 30 minutos | D22: =IF(D8="x",1,0) -> 0 | E22: =IF(E8="x",D22+1,0) -> 0 | F22: =IF(F8="x",E22+1,0) -> 0 | G22: =IF(G8="x",F22+1,0) -> 0 | H22: =IF(H8="x",G22+1,0) -> 0 | I22: =IF(I8="x",H22+1,0) -> 0 | J22: =IF(J8="x",I22+1,0) -> 0 | K22: =IF(K8="x",J22+1,0) -> 0 | L22: =IF(L8="x",K22+1,0) -> 0 | ... AH22: =IF(AH8="x",AG22+1,0) -> 0
B23: =IF($B9="","",$B9) -> Revisar pendientes de la semana | D23: =IF(D9="x",1,0) -> 0 | E23: =IF(E9="x",D23+1,0) -> 0 | F23: =IF(F9="x",E23+1,0) -> 0 | G23: =IF(G9="x",F23+1,0) -> 0 | H23: =IF(H9="x",G23+1,0) -> 0 | I23: =IF(I9="x",H23+1,0) -> 0 | J23: =IF(J9="x",I23+1,0) -> 0 | K23: =IF(K9="x",J23+1,0) -> 0 | L23: =IF(L9="x",K23+1,0) -> 0 | ... AH23: =IF(AH9="x",AG23+1,0) -> 0
B24: =IF($B10="","",$B10) -> Practicar guitarra 15 minutos | D24: =IF(D10="x",1,0) -> 0 | E24: =IF(E10="x",D24+1,0) -> 0 | F24: =IF(F10="x",E24+1,0) -> 0 | G24: =IF(G10="x",F24+1,0) -> 0 | H24: =IF(H10="x",G24+1,0) -> 0 | I24: =IF(I10="x",H24+1,0) -> 0 | J24: =IF(J10="x",I24+1,0) -> 0 | K24: =IF(K10="x",J24+1,0) -> 0 | L24: =IF(L10="x",K24+1,0) -> 0 | ... AH24: =IF(AH10="x",AG24+1,0) -> 0
B25: =IF($B11="","",$B11) | D25: =IF(D11="x",1,0) -> 0 | E25: =IF(E11="x",D25+1,0) -> 0 | F25: =IF(F11="x",E25+1,0) -> 0 | G25: =IF(G11="x",F25+1,0) -> 0 | H25: =IF(H11="x",G25+1,0) -> 0 | I25: =IF(I11="x",H25+1,0) -> 0 | J25: =IF(J11="x",I25+1,0) -> 0 | K25: =IF(K11="x",J25+1,0) -> 0 | L25: =IF(L11="x",K25+1,0) -> 0 | ... AH25: =IF(AH11="x",AG25+1,0) -> 0
B26: =IF($B12="","",$B12) | D26: =IF(D12="x",1,0) -> 0 | E26: =IF(E12="x",D26+1,0) -> 0 | F26: =IF(F12="x",E26+1,0) -> 0 | G26: =IF(G12="x",F26+1,0) -> 0 | H26: =IF(H12="x",G26+1,0) -> 0 | I26: =IF(I12="x",H26+1,0) -> 0 | J26: =IF(J12="x",I26+1,0) -> 0 | K26: =IF(K12="x",J26+1,0) -> 0 | L26: =IF(L12="x",K26+1,0) -> 0 | ... AH26: =IF(AH12="x",AG26+1,0) -> 0
B27: =IF($B13="","",$B13) | D27: =IF(D13="x",1,0) -> 0 | E27: =IF(E13="x",D27+1,0) -> 0 | F27: =IF(F13="x",E27+1,0) -> 0 | G27: =IF(G13="x",F27+1,0) -> 0 | H27: =IF(H13="x",G27+1,0) -> 0 | I27: =IF(I13="x",H27+1,0) -> 0 | J27: =IF(J13="x",I27+1,0) -> 0 | K27: =IF(K13="x",J27+1,0) -> 0 | L27: =IF(L13="x",K27+1,0) -> 0 | ... AH27: =IF(AH13="x",AG27+1,0) -> 0
B28: =IF($B14="","",$B14) | D28: =IF(D14="x",1,0) -> 0 | E28: =IF(E14="x",D28+1,0) -> 0 | F28: =IF(F14="x",E28+1,0) -> 0 | G28: =IF(G14="x",F28+1,0) -> 0 | H28: =IF(H14="x",G28+1,0) -> 0 | I28: =IF(I14="x",H28+1,0) -> 0 | J28: =IF(J14="x",I28+1,0) -> 0 | K28: =IF(K14="x",J28+1,0) -> 0 | L28: =IF(L14="x",K28+1,0) -> 0 | ... AH28: =IF(AH14="x",AG28+1,0) -> 0
B29: =IF($B15="","",$B15) | D29: =IF(D15="x",1,0) -> 0 | E29: =IF(E15="x",D29+1,0) -> 0 | F29: =IF(F15="x",E29+1,0) -> 0 | G29: =IF(G15="x",F29+1,0) -> 0 | H29: =IF(H15="x",G29+1,0) -> 0 | I29: =IF(I15="x",H29+1,0) -> 0 | J29: =IF(J15="x",I29+1,0) -> 0 | K29: =IF(K15="x",J29+1,0) -> 0 | L29: =IF(L15="x",K29+1,0) -> 0 | ... AH29: =IF(AH15="x",AG29+1,0) -> 0
B30: =IF($B16="","",$B16) | D30: =IF(D16="x",1,0) -> 0 | E30: =IF(E16="x",D30+1,0) -> 0 | F30: =IF(F16="x",E30+1,0) -> 0 | G30: =IF(G16="x",F30+1,0) -> 0 | H30: =IF(H16="x",G30+1,0) -> 0 | I30: =IF(I16="x",H30+1,0) -> 0 | J30: =IF(J16="x",I30+1,0) -> 0 | K30: =IF(K16="x",J30+1,0) -> 0 | L30: =IF(L16="x",K30+1,0) -> 0 | ... AH30: =IF(AH16="x",AG30+1,0) -> 0
B31: =IF($B17="","",$B17) | D31: =IF(D17="x",1,0) -> 0 | E31: =IF(E17="x",D31+1,0) -> 0 | F31: =IF(F17="x",E31+1,0) -> 0 | G31: =IF(G17="x",F31+1,0) -> 0 | H31: =IF(H17="x",G31+1,0) -> 0 | I31: =IF(I17="x",H31+1,0) -> 0 | J31: =IF(J17="x",I31+1,0) -> 0 | K31: =IF(K17="x",J31+1,0) -> 0 | L31: =IF(L17="x",K31+1,0) -> 0 | ... AH31: =IF(AH17="x",AG31+1,0) -> 0
B32: =IF($B18="","",$B18) | D32: =IF(D18="x",1,0) -> 0 | E32: =IF(E18="x",D32+1,0) -> 0 | F32: =IF(F18="x",E32+1,0) -> 0 | G32: =IF(G18="x",F32+1,0) -> 0 | H32: =IF(H18="x",G32+1,0) -> 0 | I32: =IF(I18="x",H32+1,0) -> 0 | J32: =IF(J18="x",I32+1,0) -> 0 | K32: =IF(K18="x",J32+1,0) -> 0 | L32: =IF(L18="x",K32+1,0) -> 0 | ... AH32: =IF(AH18="x",AG32+1,0) -> 0

Sheet Febrero
A1: FEBRERO 2026
A2: Marca con una X cada día que cumpliste. Todo lo demás se calcula solo.
A3: Jesús González · https://jesus-site-silk.vercel.app/
D5: D | E5: L | F5: M | G5: M | H5: J | I5: V | J5: S | K5: D | L5: L | M5: M | N5: M | O5: J | P5: V | Q5: S | R5: D | S5: L | T5: M | U5: M | V5: J | W5: V | X5: S | Y5: D | Z5: L | AA5: M | AB5: M | AC5: J | AD5: V | AE5: S
B6: Hábito | C6: Meta | D6: 1 | E6: 2 | F6: 3 | G6: 4 | H6: 5 | I6: 6 | J6: 7 | K6: 8 | L6: 9 | M6: 10 | N6: 11 | O6: 12 | P6: 13 | Q6: 14 | R6: 15 | S6: 16 | T6: 17 | U6: 18 | V6: 19 | W6: 20 | X6: 21 | Y6: 22 | Z6: 23 | AA6: 24 | AB6: 25 | AC6: 26 | AD6: 27 | AE6: 28 | AF6: Hechos | AG6: Meta mes | AH6: % Logro | AI6: Racha máx.
B7: ='Mis Hábitos'!$B$7 -> Leer 10 páginas | C7: =IF('Mis Hábitos'!$B$7="","",'Mis Hábitos'!$F$7) -> 7 | AF7: =IF($B7="","",COUNTIF(D7:AE7,"x")) -> 0 | AG7: =IF(OR($B7="",$C7=""),"",ROUND($C7*28/7,0)) -> 28 | AH7: =IF(OR($B7="",AG7="",AG7=0),"",AF7/AG7) -> 0 | AI7: =IF($B7="","",MAX(D21:AE21)) -> 0
B8: ='Mis Hábitos'!$B$8 -> Caminar 30 minutos | C8: =IF('Mis Hábitos'!$B$8="","",'Mis Hábitos'!$F$8) -> 5 | AF8: =IF($B8="","",COUNTIF(D8:AE8,"x")) -> 0 | AG8: =IF(OR($B8="",$C8=""),"",ROUND($C8*28/7,0)) -> 20 | AH8: =IF(OR($B8="",AG8="",AG8=0),"",AF8/AG8) -> 0 | AI8: =IF($B8="","",MAX(D22:AE22)) -> 0
B9: ='Mis Hábitos'!$B$9 -> Revisar pendientes de la semana | C9: =IF('Mis Hábitos'!$B$9="","",'Mis Hábitos'!$F$9) -> 1 | AF9: =IF($B9="","",COUNTIF(D9:AE9,"x")) -> 0 | AG9: =IF(OR($B9="",$C9=""),"",ROUND($C9*28/7,0)) -> 4 | AH9: =IF(OR($B9="",AG9="",AG9=0),"",AF9/AG9) -> 0 | AI9: =IF($B9="","",MAX(D23:AE23)) -> 0
B10: ='Mis Hábitos'!$B$10 -> Practicar guitarra 15 minutos | C10: =IF('Mis Hábitos'!$B$10="","",'Mis Hábitos'!$F$10) -> 3 | AF10: =IF($B10="","",COUNTIF(D10:AE10,"x")) -> 0 | AG10: =IF(OR($B10="",$C10=""),"",ROUND($C10*28/7,0)) -> 12 | AH10: =IF(OR($B10="",AG10="",AG10=0),"",AF10/AG10) -> 0 | AI10: =IF($B10="","",MAX(D24:AE24)) -> 0
B11: ='Mis Hábitos'!$B$11 -> 0 | C11: =IF('Mis Hábitos'!$B$11="","",'Mis Hábitos'!$F$11) | AF11: =IF($B11="","",COUNTIF(D11:AE11,"x")) | AG11: =IF(OR($B11="",$C11=""),"",ROUND($C11*28/7,0)) | AH11: =IF(OR($B11="",AG11="",AG11=0),"",AF11/AG11) | AI11: =IF($B11="","",MAX(D25:AE25))
B12: ='Mis Hábitos'!$B$12 -> 0 | C12: =IF('Mis Hábitos'!$B$12="","",'Mis Hábitos'!$F$12) | AF12: =IF($B12="","",COUNTIF(D12:AE12,"x")) | AG12: =IF(OR($B12="",$C12=""),"",ROUND($C12*28/7,0)) | AH12: =IF(OR($B12="",AG12="",AG12=0),"",AF12/AG12) | AI12: =IF($B12="","",MAX(D26:AE26))
B13: ='Mis Hábitos'!$B$13 -> 0 | C13: =IF('Mis Hábitos'!$B$13="","",'Mis Hábitos'!$F$13) | AF13: =IF($B13="","",COUNTIF(D13:AE13,"x")) | AG13: =IF(OR($B13="",$C13=""),"",ROUND($C13*28/7,0)) | AH13: =IF(OR($B13="",AG13="",AG13=0),"",AF13/AG13) | AI13: =IF($B13="","",MAX(D27:AE27))
B14: ='Mis Hábitos'!$B$14 -> 0 | C14: =IF('Mis Hábitos'!$B$14="","",'Mis Hábitos'!$F$14) | AF14: =IF($B14="","",COUNTIF(D14:AE14,"x")) | AG14: =IF(OR($B14="",$C14=""),"",ROUND($C14*28/7,0)) | AH14: =IF(OR($B14="",AG14="",AG14=0),"",AF14/AG14) | AI14: =IF($B14="","",MAX(D28:AE28))
B15: ='Mis Hábitos'!$B$15 -> 0 | C15: =IF('Mis Hábitos'!$B$15="","",'Mis Hábitos'!$F$15) | AF15: =IF($B15="","",COUNTIF(D15:AE15,"x")) | AG15: =IF(OR($B15="",$C15=""),"",ROUND($C15*28/7,0)) | AH15: =IF(OR($B15="",AG15="",AG15=0),"",AF15/AG15) | AI15: =IF($B15="","",MAX(D29:AE29))
B16: ='Mis Hábitos'!$B$16 -> 0 | C16: =IF('Mis Hábitos'!$B$16="","",'Mis Hábitos'!$F$16) | AF16: =IF($B16="","",COUNTIF(D16:AE16,"x")) | AG16: =IF(OR($B16="",$C16=""),"",ROUND($C16*28/7,0)) | AH16: =IF(OR($B16="",AG16="",AG16=0),"",AF16/AG16) | AI16: =IF($B16="","",MAX(D30:AE30))
B17: ='Mis Hábitos'!$B$17 -> 0 | C17: =IF('Mis Hábitos'!$B$17="","",'Mis Hábitos'!$F$17) | AF17: =IF($B17="","",COUNTIF(D17:AE17,"x")) | AG17: =IF(OR($B17="",$C17=""),"",ROUND($C17*28/7,0)) | AH17: =IF(OR($B17="",AG17="",AG17=0),"",AF17/AG17) | AI17: =IF($B17="","",MAX(D31:AE31))
B18: ='Mis Hábitos'!$B$18 -> 0 | C18: =IF('Mis Hábitos'!$B$18="","",'Mis Hábitos'!$F$18) | AF18: =IF($B18="","",COUNTIF(D18:AE18,"x")) | AG18: =IF(OR($B18="",$C18=""),"",ROUND($C18*28/7,0)) | AH18: =IF(OR($B18="",AG18="",AG18=0),"",AF18/AG18) | AI18: =IF($B18="","",MAX(D32:AE32))
B19: Cumplidos del día | D19: =COUNTIF(D7:D18,"x") -> 0 | E19: =COUNTIF(E7:E18,"x") -> 0 | F19: =COUNTIF(F7:F18,"x") -> 0 | G19: =COUNTIF(G7:G18,"x") -> 0 | H19: =COUNTIF(H7:H18,"x") -> 0 | I19: =COUNTIF(I7:I18,"x") -> 0 | J19: =COUNTIF(J7:J18,"x") -> 0 | K19: =COUNTIF(K7:K18,"x") -> 0 | ... AE19: =COUNTIF(AE7:AE18,"x") -> 0
B20: x = cumplido · - = no aplicaba ese día · vacío = no se cumplió La columna del día de hoy aparece con borde naranja.
B21: =IF($B7="","",$B7) -> Leer 10 páginas | D21: =IF(D7="x",1,0) -> 0 | E21: =IF(E7="x",D21+1,0) -> 0 | F21: =IF(F7="x",E21+1,0) -> 0 | G21: =IF(G7="x",F21+1,0) -> 0 | H21: =IF(H7="x",G21+1,0) -> 0 | I21: =IF(I7="x",H21+1,0) -> 0 | J21: =IF(J7="x",I21+1,0) -> 0 | K21: =IF(K7="x",J21+1,0) -> 0 | L21: =IF(L7="x",K21+1,0) -> 0 | ... AE21: =IF(AE7="x",AD21+1,0) -> 0
B22: =IF($B8="","",$B8) -> Caminar 30 minutos | D22: =IF(D8="x",1,0) -> 0 | E22: =IF(E8="x",D22+1,0) -> 0 | F22: =IF(F8="x",E22+1,0) -> 0 | G22: =IF(G8="x",F22+1,0) -> 0 | H22: =IF(H8="x",G22+1,0) -> 0 | I22: =IF(I8="x",H22+1,0) -> 0 | J22: =IF(J8="x",I22+1,0) -> 0 | K22: =IF(K8="x",J22+1,0) -> 0 | L22: =IF(L8="x",K22+1,0) -> 0 | ... AE22: =IF(AE8="x",AD22+1,0) -> 0
B23: =IF($B9="","",$B9) -> Revisar pendientes de la semana | D23: =IF(D9="x",1,0) -> 0 | E23: =IF(E9="x",D23+1,0) -> 0 | F23: =IF(F9="x",E23+1,0) -> 0 | G23: =IF(G9="x",F23+1,0) -> 0 | H23: =IF(H9="x",G23+1,0) -> 0 | I23: =IF(I9="x",H23+1,0) -> 0 | J23: =IF(J9="x",I23+1,0) -> 0 | K23: =IF(K9="x",J23+1,0) -> 0 | L23: =IF(L9="x",K23+1,0) -> 0 | ... AE23: =IF(AE9="x",AD23+1,0) -> 0
B24: =IF($B10="","",$B10) -> Practicar guitarra 15 minutos | D24: =IF(D10="x",1,0) -> 0 | E24: =IF(E10="x",D24+1,0) -> 0 | F24: =IF(F10="x",E24+1,0) -> 0 | G24: =IF(G10="x",F24+1,0) -> 0 | H24: =IF(H10="x",G24+1,0) -> 0 | I24: =IF(I10="x",H24+1,0) -> 0 | J24: =IF(J10="x",I24+1,0) -> 0 | K24: =IF(K10="x",J24+1,0) -> 0 | L24: =IF(L10="x",K24+1,0) -> 0 | ... AE24: =IF(AE10="x",AD24+1,0) -> 0
B25: =IF($B11="","",$B11) | D25: =IF(D11="x",1,0) -> 0 | E25: =IF(E11="x",D25+1,0) -> 0 | F25: =IF(F11="x",E25+1,0) -> 0 | G25: =IF(G11="x",F25+1,0) -> 0 | H25: =IF(H11="x",G25+1,0) -> 0 | I25: =IF(I11="x",H25+1,0) -> 0 | J25: =IF(J11="x",I25+1,0) -> 0 | K25: =IF(K11="x",J25+1,0) -> 0 | L25: =IF(L11="x",K25+1,0) -> 0 | ... AE25: =IF(AE11="x",AD25+1,0) -> 0
B26: =IF($B12="","",$B12) | D26: =IF(D12="x",1,0) -> 0 | E26: =IF(E12="x",D26+1,0) -> 0 | F26: =IF(F12="x",E26+1,0) -> 0 | G26: =IF(G12="x",F26+1,0) -> 0 | H26: =IF(H12="x",G26+1,0) -> 0 | I26: =IF(I12="x",H26+1,0) -> 0 | J26: =IF(J12="x",I26+1,0) -> 0 | K26: =IF(K12="x",J26+1,0) -> 0 | L26: =IF(L12="x",K26+1,0) -> 0 | ... AE26: =IF(AE12="x",AD26+1,0) -> 0
B27: =IF($B13="","",$B13) | D27: =IF(D13="x",1,0) -> 0 | E27: =IF(E13="x",D27+1,0) -> 0 | F27: =IF(F13="x",E27+1,0) -> 0 | G27: =IF(G13="x",F27+1,0) -> 0 | H27: =IF(H13="x",G27+1,0) -> 0 | I27: =IF(I13="x",H27+1,0) -> 0 | J27: =IF(J13="x",I27+1,0) -> 0 | K27: =IF(K13="x",J27+1,0) -> 0 | L27: =IF(L13="x",K27+1,0) -> 0 | ... AE27: =IF(AE13="x",AD27+1,0) -> 0
B28: =IF($B14="","",$B14) | D28: =IF(D14="x",1,0) -> 0 | E28: =IF(E14="x",D28+1,0) -> 0 | F28: =IF(F14="x",E28+1,0) -> 0 | G28: =IF(G14="x",F28+1,0) -> 0 | H28: =IF(H14="x",G28+1,0) -> 0 | I28: =IF(I14="x",H28+1,0) -> 0 | J28: =IF(J14="x",I28+1,0) -> 0 | K28: =IF(K14="x",J28+1,0) -> 0 | L28: =IF(L14="x",K28+1,0) -> 0 | ... AE28: =IF(AE14="x",AD28+1,0) -> 0
B29: =IF($B15="","",$B15) | D29: =IF(D15="x",1,0) -> 0 | E29: =IF(E15="x",D29+1,0) -> 0 | F29: =IF(F15="x",E29+1,0) -> 0 | G29: =IF(G15="x",F29+1,0) -> 0 | H29: =IF(H15="x",G29+1,0) -> 0 | I29: =IF(I15="x",H29+1,0) -> 0 | J29: =IF(J15="x",I29+1,0) -> 0 | K29: =IF(K15="x",J29+1,0) -> 0 | L29: =IF(L15="x",K29+1,0) -> 0 | ... AE29: =IF(AE15="x",AD29+1,0) -> 0
B30: =IF($B16="","",$B16) | D30: =IF(D16="x",1,0) -> 0 | E30: =IF(E16="x",D30+1,0) -> 0 | F30: =IF(F16="x",E30+1,0) -> 0 | G30: =IF(G16="x",F30+1,0) -> 0 | H30: =IF(H16="x",G30+1,0) -> 0 | I30: =IF(I16="x",H30+1,0) -> 0 | J30: =IF(J16="x",I30+1,0) -> 0 | K30: =IF(K16="x",J30+1,0) -> 0 | L30: =IF(L16="x",K30+1,0) -> 0 | ... AE30: =IF(AE16="x",AD30+1,0) -> 0
B31: =IF($B17="","",$B17) | D31: =IF(D17="x",1,0) -> 0 | E31: =IF(E17="x",D31+1,0) -> 0 | F31: =IF(F17="x",E31+1,0) -> 0 | G31: =IF(G17="x",F31+1,0) -> 0 | H31: =IF(H17="x",G31+1,0) -> 0 | I31: =IF(I17="x",H31+1,0) -> 0 | J31: =IF(J17="x",I31+1,0) -> 0 | K31: =IF(K17="x",J31+1,0) -> 0 | L31: =IF(L17="x",K31+1,0) -> 0 | ... AE31: =IF(AE17="x",AD31+1,0) -> 0
B32: =IF($B18="","",$B18) | D32: =IF(D18="x",1,0) -> 0 | E32: =IF(E18="x",D32+1,0) -> 0 | F32: =IF(F18="x",E32+1,0) -> 0 | G32: =IF(G18="x",F32+1,0) -> 0 | H32: =IF(H18="x",G32+1,0) -> 0 | I32: =IF(I18="x",H32+1,0) -> 0 | J32: =IF(J18="x",I32+1,0) -> 0 | K32: =IF(K18="x",J32+1,0) -> 0 | L32: =IF(L18="x",K32+1,0) -> 0 | ... AE32: =IF(AE18="x",AD32+1,0) -> 0

Sheet Marzo
A1: MARZO 2026
A2: Marca con una X cada día que cumpliste. Todo lo demás se calcula solo.
A3: Jesús González · https://jesus-site-silk.vercel.app/
D5: D | E5: L | F5: M | G5: M | H5: J | I5: V | J5: S | K5: D | L5: L | M5: M | N5: M | O5: J | P5: V | Q5: S | R5: D | S5: L | T5: M | U5: M | V5: J | W5: V | X5: S | Y5: D | Z5: L | AA5: M | AB5: M | AC5: J | AD5: V | AE5: S | AF5: D | AG5: L | AH5: M
B6: Hábito | C6: Meta | D6: 1 | E6: 2 | F6: 3 | G6: 4 | H6: 5 | I6: 6 | J6: 7 | K6: 8 | L6: 9 | M6: 10 | N6: 11 | O6: 12 | P6: 13 | Q6: 14 | R6: 15 | S6: 16 | T6: 17 | U6: 18 | V6: 19 | W6: 20 | X6: 21 | Y6: 22 | Z6: 23 | AA6: 24 | AB6: 25 | AC6: 26 | AD6: 27 | AE6: 28 | AF6: 29 | AG6: 30 | AH6: 31 | AI6: Hechos | AJ6: Meta mes | AK6: % Logro | AL6: Racha máx.
B7: ='Mis Hábitos'!$B$7 -> Leer 10 páginas | C7: =IF('Mis Hábitos'!$B$7="","",'Mis Hábitos'!$F$7) -> 7 | AI7: =IF($B7="","",COUNTIF(D7:AH7,"x")) -> 0 | AJ7: =IF(OR($B7="",$C7=""),"",ROUND($C7*31/7,0)) -> 31 | AK7: =IF(OR($B7="",AJ7="",AJ7=0),"",AI7/AJ7) -> 0 | AL7: =IF($B7="","",MAX(D21:AH21)) -> 0
B8: ='Mis Hábitos'!$B$8 -> Caminar 30 minutos | C8: =IF('Mis Hábitos'!$B$8="","",'Mis Hábitos'!$F$8) -> 5 | AI8: =IF($B8="","",COUNTIF(D8:AH8,"x")) -> 0 | AJ8: =IF(OR($B8="",$C8=""),"",ROUND($C8*31/7,0)) -> 22 | AK8: =IF(OR($B8="",AJ8="",AJ8=0),"",AI8/AJ8) -> 0 | AL8: =IF($B8="","",MAX(D22:AH22)) -> 0
B9: ='Mis Hábitos'!$B$9 -> Revisar pendientes de la semana | C9: =IF('Mis Hábitos'!$B$9="","",'Mis Hábitos'!$F$9) -> 1 | AI9: =IF($B9="","",COUNTIF(D9:AH9,"x")) -> 0 | AJ9: =IF(OR($B9="",$C9=""),"",ROUND($C9*31/7,0)) -> 4 | AK9: =IF(OR($B9="",AJ9="",AJ9=0),"",AI9/AJ9) -> 0 | AL9: =IF($B9="","",MAX(D23:AH23)) -> 0
B10: ='Mis Hábitos'!$B$10 -> Practicar guitarra 15 minutos | C10: =IF('Mis Hábitos'!$B$10="","",'Mis Hábitos'!$F$10) -> 3 | AI10: =IF($B10="","",COUNTIF(D10:AH10,"x")) -> 0 | AJ10: =IF(OR($B10="",$C10=""),"",ROUND($C10*31/7,0)) -> 13 | AK10: =IF(OR($B10="",AJ10="",AJ10=0),"",AI10/AJ10) -> 0 | AL10: =IF($B10="","",MAX(D24:AH24)) -> 0
B11: ='Mis Hábitos'!$B$11 -> 0 | C11: =IF('Mis Hábitos'!$B$11="","",'Mis Hábitos'!$F$11) | AI11: =IF($B11="","",COUNTIF(D11:AH11,"x")) | AJ11: =IF(OR($B11="",$C11=""),"",ROUND($C11*31/7,0)) | AK11: =IF(OR($B11="",AJ11="",AJ11=0),"",AI11/AJ11) | AL11: =IF($B11="","",MAX(D25:AH25))
B12: ='Mis Hábitos'!$B$12 -> 0 | C12: =IF('Mis Hábitos'!$B$12="","",'Mis Hábitos'!$F$12) | AI12: =IF($B12="","",COUNTIF(D12:AH12,"x")) | AJ12: =IF(OR($B12="",$C12=""),"",ROUND($C12*31/7,0)) | AK12: =IF(OR($B12="",AJ12="",AJ12=0),"",AI12/AJ12) | AL12: =IF($B12="","",MAX(D26:AH26))
B13: ='Mis Hábitos'!$B$13 -> 0 | C13: =IF('Mis Hábitos'!$B$13="","",'Mis Hábitos'!$F$13) | AI13: =IF($B13="","",COUNTIF(D13:AH13,"x")) | AJ13: =IF(OR($B13="",$C13=""),"",ROUND($C13*31/7,0)) | AK13: =IF(OR($B13="",AJ13="",AJ13=0),"",AI13/AJ13) | AL13: =IF($B13="","",MAX(D27:AH27))
B14: ='Mis Hábitos'!$B$14 -> 0 | C14: =IF('Mis Hábitos'!$B$14="","",'Mis Hábitos'!$F$14) | AI14: =IF($B14="","",COUNTIF(D14:AH14,"x")) | AJ14: =IF(OR($B14="",$C14=""),"",ROUND($C14*31/7,0)) | AK14: =IF(OR($B14="",AJ14="",AJ14=0),"",AI14/AJ14) | AL14: =IF($B14="","",MAX(D28:AH28))
B15: ='Mis Hábitos'!$B$15 -> 0 | C15: =IF('Mis Hábitos'!$B$15="","",'Mis Hábitos'!$F$15) | AI15: =IF($B15="","",COUNTIF(D15:AH15,"x")) | AJ15: =IF(OR($B15="",$C15=""),"",ROUND($C15*31/7,0)) | AK15: =IF(OR($B15="",AJ15="",AJ15=0),"",AI15/AJ15) | AL15: =IF($B15="","",MAX(D29:AH29))
B16: ='Mis Hábitos'!$B$16 -> 0 | C16: =IF('Mis Hábitos'!$B$16="","",'Mis Hábitos'!$F$16) | AI16: =IF($B16="","",COUNTIF(D16:AH16,"x")) | AJ16: =IF(OR($B16="",$C16=""),"",ROUND($C16*31/7,0)) | AK16: =IF(OR($B16="",AJ16="",AJ16=0),"",AI16/AJ16) | AL16: =IF($B16="","",MAX(D30:AH30))
B17: ='Mis Hábitos'!$B$17 -> 0 | C17: =IF('Mis Hábitos'!$B$17="","",'Mis Hábitos'!$F$17) | AI17: =IF($B17="","",COUNTIF(D17:AH17,"x")) | AJ17: =IF(OR($B17="",$C17=""),"",ROUND($C17*31/7,0)) | AK17: =IF(OR($B17="",AJ17="",AJ17=0),"",AI17/AJ17) | AL17: =IF($B17="","",MAX(D31:AH31))
B18: ='Mis Hábitos'!$B$18 -> 0 | C18: =IF('Mis Hábitos'!$B$18="","",'Mis Hábitos'!$F$18) | AI18: =IF($B18="","",COUNTIF(D18:AH18,"x")) | AJ18: =IF(OR($B18="",$C18=""),"",ROUND($C18*31/7,0)) | AK18: =IF(OR($B18="",AJ18="",AJ18=0),"",AI18/AJ18) | AL18: =IF($B18="","",MAX(D32:AH32))
B19: Cumplidos del día | D19: =COUNTIF(D7:D18,"x") -> 0 | E19: =COUNTIF(E7:E18,"x") -> 0 | F19: =COUNTIF(F7:F18,"x") -> 0 | G19: =COUNTIF(G7:G18,"x") -> 0 | H19: =COUNTIF(H7:H18,"x") -> 0 | I19: =COUNTIF(I7:I18,"x") -> 0 | J19: =COUNTIF(J7:J18,"x") -> 0 | K19: =COUNTIF(K7:K18,"x") -> 0 | ... AH19: =COUNTIF(AH7:AH18,"x") -> 0
B20: x = cumplido · - = no aplicaba ese día · vacío = no se cumplió La columna del día de hoy aparece con borde naranja.
B21: =IF($B7="","",$B7) -> Leer 10 páginas | D21: =IF(D7="x",1,0) -> 0 | E21: =IF(E7="x",D21+1,0) -> 0 | F21: =IF(F7="x",E21+1,0) -> 0 | G21: =IF(G7="x",F21+1,0) -> 0 | H21: =IF(H7="x",G21+1,0) -> 0 | I21: =IF(I7="x",H21+1,0) -> 0 | J21: =IF(J7="x",I21+1,0) -> 0 | K21: =IF(K7="x",J21+1,0) -> 0 | L21: =IF(L7="x",K21+1,0) -> 0 | ... AH21: =IF(AH7="x",AG21+1,0) -> 0
B22: =IF($B8="","",$B8) -> Caminar 30 minutos | D22: =IF(D8="x",1,0) -> 0 | E22: =IF(E8="x",D22+1,0) -> 0 | F22: =IF(F8="x",E22+1,0) -> 0 | G22: =IF(G8="x",F22+1,0) -> 0 | H22: =IF(H8="x",G22+1,0) -> 0 | I22: =IF(I8="x",H22+1,0) -> 0 | J22: =IF(J8="x",I22+1,0) -> 0 | K22: =IF(K8="x",J22+1,0) -> 0 | L22: =IF(L8="x",K22+1,0) -> 0 | ... AH22: =IF(AH8="x",AG22+1,0) -> 0
B23: =IF($B9="","",$B9) -> Revisar pendientes de la semana | D23: =IF(D9="x",1,0) -> 0 | E23: =IF(E9="x",D23+1,0) -> 0 | F23: =IF(F9="x",E23+1,0) -> 0 | G23: =IF(G9="x",F23+1,0) -> 0 | H23: =IF(H9="x",G23+1,0) -> 0 | I23: =IF(I9="x",H23+1,0) -> 0 | J23: =IF(J9="x",I23+1,0) -> 0 | K23: =IF(K9="x",J23+1,0) -> 0 | L23: =IF(L9="x",K23+1,0) -> 0 | ... AH23: =IF(AH9="x",AG23+1,0) -> 0
B24: =IF($B10="","",$B10) -> Practicar guitarra 15 minutos | D24: =IF(D10="x",1,0) -> 0 | E24: =IF(E10="x",D24+1,0) -> 0 | F24: =IF(F10="x",E24+1,0) -> 0 | G24: =IF(G10="x",F24+1,0) -> 0 | H24: =IF(H10="x",G24+1,0) -> 0 | I24: =IF(I10="x",H24+1,0) -> 0 | J24: =IF(J10="x",I24+1,0) -> 0 | K24: =IF(K10="x",J24+1,0) -> 0 | L24: =IF(L10="x",K24+1,0) -> 0 | ... AH24: =IF(AH10="x",AG24+1,0) -> 0
B25: =IF($B11="","",$B11) | D25: =IF(D11="x",1,0) -> 0 | E25: =IF(E11="x",D25+1,0) -> 0 | F25: =IF(F11="x",E25+1,0) -> 0 | G25: =IF(G11="x",F25+1,0) -> 0 | H25: =IF(H11="x",G25+1,0) -> 0 | I25: =IF(I11="x",H25+1,0) -> 0 | J25: =IF(J11="x",I25+1,0) -> 0 | K25: =IF(K11="x",J25+1,0) -> 0 | L25: =IF(L11="x",K25+1,0) -> 0 | ... AH25: =IF(AH11="x",AG25+1,0) -> 0
B26: =IF($B12="","",$B12) | D26: =IF(D12="x",1,0) -> 0 | E26: =IF(E12="x",D26+1,0) -> 0 | F26: =IF(F12="x",E26+1,0) -> 0 | G26: =IF(G12="x",F26+1,0) -> 0 | H26: =IF(H12="x",G26+1,0) -> 0 | I26: =IF(I12="x",H26+1,0) -> 0 | J26: =IF(J12="x",I26+1,0) -> 0 | K26: =IF(K12="x",J26+1,0) -> 0 | L26: =IF(L12="x",K26+1,0) -> 0 | ... AH26: =IF(AH12="x",AG26+1,0) -> 0
B27: =IF($B13="","",$B13) | D27: =IF(D13="x",1,0) -> 0 | E27: =IF(E13="x",D27+1,0) -> 0 | F27: =IF(F13="x",E27+1,0) -> 0 | G27: =IF(G13="x",F27+1,0) -> 0 | H27: =IF(H13="x",G27+1,0) -> 0 | I27: =IF(I13="x",H27+1,0) -> 0 | J27: =IF(J13="x",I27+1,0) -> 0 | K27: =IF(K13="x",J27+1,0) -> 0 | L27: =IF(L13="x",K27+1,0) -> 0 | ... AH27: =IF(AH13="x",AG27+1,0) -> 0
B28: =IF($B14="","",$B14) | D28: =IF(D14="x",1,0) -> 0 | E28: =IF(E14="x",D28+1,0) -> 0 | F28: =IF(F14="x",E28+1,0) -> 0 | G28: =IF(G14="x",F28+1,0) -> 0 | H28: =IF(H14="x",G28+1,0) -> 0 | I28: =IF(I14="x",H28+1,0) -> 0 | J28: =IF(J14="x",I28+1,0) -> 0 | K28: =IF(K14="x",J28+1,0) -> 0 | L28: =IF(L14="x",K28+1,0) -> 0 | ... AH28: =IF(AH14="x",AG28+1,0) -> 0
B29: =IF($B15="","",$B15) | D29: =IF(D15="x",1,0) -> 0 | E29: =IF(E15="x",D29+1,0) -> 0 | F29: =IF(F15="x",E29+1,0) -> 0 | G29: =IF(G15="x",F29+1,0) -> 0 | H29: =IF(H15="x",G29+1,0) -> 0 | I29: =IF(I15="x",H29+1,0) -> 0 | J29: =IF(J15="x",I29+1,0) -> 0 | K29: =IF(K15="x",J29+1,0) -> 0 | L29: =IF(L15="x",K29+1,0) -> 0 | ... AH29: =IF(AH15="x",AG29+1,0) -> 0
B30: =IF($B16="","",$B16) | D30: =IF(D16="x",1,0) -> 0 | E30: =IF(E16="x",D30+1,0) -> 0 | F30: =IF(F16="x",E30+1,0) -> 0 | G30: =IF(G16="x",F30+1,0) -> 0 | H30: =IF(H16="x",G30+1,0) -> 0 | I30: =IF(I16="x",H30+1,0) -> 0 | J30: =IF(J16="x",I30+1,0) -> 0 | K30: =IF(K16="x",J30+1,0) -> 0 | L30: =IF(L16="x",K30+1,0) -> 0 | ... AH30: =IF(AH16="x",AG30+1,0) -> 0
B31: =IF($B17="","",$B17) | D31: =IF(D17="x",1,0) -> 0 | E31: =IF(E17="x",D31+1,0) -> 0 | F31: =IF(F17="x",E31+1,0) -> 0 | G31: =IF(G17="x",F31+1,0) -> 0 | H31: =IF(H17="x",G31+1,0) -> 0 | I31: =IF(I17="x",H31+1,0) -> 0 | J31: =IF(J17="x",I31+1,0) -> 0 | K31: =IF(K17="x",J31+1,0) -> 0 | L31: =IF(L17="x",K31+1,0) -> 0 | ... AH31: =IF(AH17="x",AG31+1,0) -> 0
B32: =IF($B18="","",$B18) | D32: =IF(D18="x",1,0) -> 0 | E32: =IF(E18="x",D32+1,0) -> 0 | F32: =IF(F18="x",E32+1,0) -> 0 | G32: =IF(G18="x",F32+1,0) -> 0 | H32: =IF(H18="x",G32+1,0) -> 0 | I32: =IF(I18="x",H32+1,0) -> 0 | J32: =IF(J18="x",I32+1,0) -> 0 | K32: =IF(K18="x",J32+1,0) -> 0 | L32: =IF(L18="x",K32+1,0) -> 0 | ... AH32: =IF(AH18="x",AG32+1,0) -> 0

Sheet Abril
A1: ABRIL 2026
A2: Marca con una X cada día que cumpliste. Todo lo demás se calcula solo.
A3: Jesús González · https://jesus-site-silk.vercel.app/
D5: M | E5: J | F5: V | G5: S | H5: D | I5: L | J5: M | K5: M | L5: J | M5: V | N5: S | O5: D | P5: L | Q5: M | R5: M | S5: J | T5: V | U5: S | V5: D | W5: L | X5: M | Y5: M | Z5: J | AA5: V | AB5: S | AC5: D | AD5: L | AE5: M | AF5: M | AG5: J
B6: Hábito | C6: Meta | D6: 1 | E6: 2 | F6: 3 | G6: 4 | H6: 5 | I6: 6 | J6: 7 | K6: 8 | L6: 9 | M6: 10 | N6: 11 | O6: 12 | P6: 13 | Q6: 14 | R6: 15 | S6: 16 | T6: 17 | U6: 18 | V6: 19 | W6: 20 | X6: 21 | Y6: 22 | Z6: 23 | AA6: 24 | AB6: 25 | AC6: 26 | AD6: 27 | AE6: 28 | AF6: 29 | AG6: 30 | AH6: Hechos | AI6: Meta mes | AJ6: % Logro | AK6: Racha máx.
B7: ='Mis Hábitos'!$B$7 -> Leer 10 páginas | C7: =IF('Mis Hábitos'!$B$7="","",'Mis Hábitos'!$F$7) -> 7 | AH7: =IF($B7="","",COUNTIF(D7:AG7,"x")) -> 0 | AI7: =IF(OR($B7="",$C7=""),"",ROUND($C7*30/7,0)) -> 30 | AJ7: =IF(OR($B7="",AI7="",AI7=0),"",AH7/AI7) -> 0 | AK7: =IF($B7="","",MAX(D21:AG21)) -> 0
B8: ='Mis Hábitos'!$B$8 -> Caminar 30 minutos | C8: =IF('Mis Hábitos'!$B$8="","",'Mis Hábitos'!$F$8) -> 5 | AH8: =IF($B8="","",COUNTIF(D8:AG8,"x")) -> 0 | AI8: =IF(OR($B8="",$C8=""),"",ROUND($C8*30/7,0)) -> 21 | AJ8: =IF(OR($B8="",AI8="",AI8=0),"",AH8/AI8) -> 0 | AK8: =IF($B8="","",MAX(D22:AG22)) -> 0
B9: ='Mis Hábitos'!$B$9 -> Revisar pendientes de la semana | C9: =IF('Mis Hábitos'!$B$9="","",'Mis Hábitos'!$F$9) -> 1 | AH9: =IF($B9="","",COUNTIF(D9:AG9,"x")) -> 0 | AI9: =IF(OR($B9="",$C9=""),"",ROUND($C9*30/7,0)) -> 4 | AJ9: =IF(OR($B9="",AI9="",AI9=0),"",AH9/AI9) -> 0 | AK9: =IF($B9="","",MAX(D23:AG23)) -> 0
B10: ='Mis Hábitos'!$B$10 -> Practicar guitarra 15 minutos | C10: =IF('Mis Hábitos'!$B$10="","",'Mis Hábitos'!$F$10) -> 3 | AH10: =IF($B10="","",COUNTIF(D10:AG10,"x")) -> 0 | AI10: =IF(OR($B10="",$C10=""),"",ROUND($C10*30/7,0)) -> 13 | AJ10: =IF(OR($B10="",AI10="",AI10=0),"",AH10/AI10) -> 0 | AK10: =IF($B10="","",MAX(D24:AG24)) -> 0
B11: ='Mis Hábitos'!$B$11 -> 0 | C11: =IF('Mis Hábitos'!$B$11="","",'Mis Hábitos'!$F$11) | AH11: =IF($B11="","",COUNTIF(D11:AG11,"x")) | AI11: =IF(OR($B11="",$C11=""),"",ROUND($C11*30/7,0)) | AJ11: =IF(OR($B11="",AI11="",AI11=0),"",AH11/AI11) | AK11: =IF($B11="","",MAX(D25:AG25))
B12: ='Mis Hábitos'!$B$12 -> 0 | C12: =IF('Mis Hábitos'!$B$12="","",'Mis Hábitos'!$F$12) | AH12: =IF($B12="","",COUNTIF(D12:AG12,"x")) | AI12: =IF(OR($B12="",$C12=""),"",ROUND($C12*30/7,0)) | AJ12: =IF(OR($B12="",AI12="",AI12=0),"",AH12/AI12) | AK12: =IF($B12="","",MAX(D26:AG26))
B13: ='Mis Hábitos'!$B$13 -> 0 | C13: =IF('Mis Hábitos'!$B$13="","",'Mis Hábitos'!$F$13) | AH13: =IF($B13="","",COUNTIF(D13:AG13,"x")) | AI13: =IF(OR($B13="",$C13=""),"",ROUND($C13*30/7,0)) | AJ13: =IF(OR($B13="",AI13="",AI13=0),"",AH13/AI13) | AK13: =IF($B13="","",MAX(D27:AG27))
B14: ='Mis Hábitos'!$B$14 -> 0 | C14: =IF('Mis Hábitos'!$B$14="","",'Mis Hábitos'!$F$14) | AH14: =IF($B14="","",COUNTIF(D14:AG14,"x")) | AI14: =IF(OR($B14="",$C14=""),"",ROUND($C14*30/7,0)) | AJ14: =IF(OR($B14="",AI14="",AI14=0),"",AH14/AI14) | AK14: =IF($B14="","",MAX(D28:AG28))
B15: ='Mis Hábitos'!$B$15 -> 0 | C15: =IF('Mis Hábitos'!$B$15="","",'Mis Hábitos'!$F$15) | AH15: =IF($B15="","",COUNTIF(D15:AG15,"x")) | AI15: =IF(OR($B15="",$C15=""),"",ROUND($C15*30/7,0)) | AJ15: =IF(OR($B15="",AI15="",AI15=0),"",AH15/AI15) | AK15: =IF($B15="","",MAX(D29:AG29))
B16: ='Mis Hábitos'!$B$16 -> 0 | C16: =IF('Mis Hábitos'!$B$16="","",'Mis Hábitos'!$F$16) | AH16: =IF($B16="","",COUNTIF(D16:AG16,"x")) | AI16: =IF(OR($B16="",$C16=""),"",ROUND($C16*30/7,0)) | AJ16: =IF(OR($B16="",AI16="",AI16=0),"",AH16/AI16) | AK16: =IF($B16="","",MAX(D30:AG30))
B17: ='Mis Hábitos'!$B$17 -> 0 | C17: =IF('Mis Hábitos'!$B$17="","",'Mis Hábitos'!$F$17) | AH17: =IF($B17="","",COUNTIF(D17:AG17,"x")) | AI17: =IF(OR($B17="",$C17=""),"",ROUND($C17*30/7,0)) | AJ17: =IF(OR($B17="",AI17="",AI17=0),"",AH17/AI17) | AK17: =IF($B17="","",MAX(D31:AG31))
B18: ='Mis Hábitos'!$B$18 -> 0 | C18: =IF('Mis Hábitos'!$B$18="","",'Mis Hábitos'!$F$18) | AH18: =IF($B18="","",COUNTIF(D18:AG18,"x")) | AI18: =IF(OR($B18="",$C18=""),"",ROUND($C18*30/7,0)) | AJ18: =IF(OR($B18="",AI18="",AI18=0),"",AH18/AI18) | AK18: =IF($B18="","",MAX(D32:AG32))
B19: Cumplidos del día | D19: =COUNTIF(D7:D18,"x") -> 0 | E19: =COUNTIF(E7:E18,"x") -> 0 | F19: =COUNTIF(F7:F18,"x") -> 0 | G19: =COUNTIF(G7:G18,"x") -> 0 | H19: =COUNTIF(H7:H18,"x") -> 0 | I19: =COUNTIF(I7:I18,"x") -> 0 | J19: =COUNTIF(J7:J18,"x") -> 0 | K19: =COUNTIF(K7:K18,"x") -> 0 | ... AG19: =COUNTIF(AG7:AG18,"x") -> 0
B20: x = cumplido · - = no aplicaba ese día · vacío = no se cumplió La columna del día de hoy aparece con borde naranja.
B21: =IF($B7="","",$B7) -> Leer 10 páginas | D21: =IF(D7="x",1,0) -> 0 | E21: =IF(E7="x",D21+1,0) -> 0 | F21: =IF(F7="x",E21+1,0) -> 0 | G21: =IF(G7="x",F21+1,0) -> 0 | H21: =IF(H7="x",G21+1,0) -> 0 | I21: =IF(I7="x",H21+1,0) -> 0 | J21: =IF(J7="x",I21+1,0) -> 0 | K21: =IF(K7="x",J21+1,0) -> 0 | L21: =IF(L7="x",K21+1,0) -> 0 | ... AG21: =IF(AG7="x",AF21+1,0) -> 0
B22: =IF($B8="","",$B8) -> Caminar 30 minutos | D22: =IF(D8="x",1,0) -> 0 | E22: =IF(E8="x",D22+1,0) -> 0 | F22: =IF(F8="x",E22+1,0) -> 0 | G22: =IF(G8="x",F22+1,0) -> 0 | H22: =IF(H8="x",G22+1,0) -> 0 | I22: =IF(I8="x",H22+1,0) -> 0 | J22: =IF(J8="x",I22+1,0) -> 0 | K22: =IF(K8="x",J22+1,0) -> 0 | L22: =IF(L8="x",K22+1,0) -> 0 | ... AG22: =IF(AG8="x",AF22+1,0) -> 0
B23: =IF($B9="","",$B9) -> Revisar pendientes de la semana | D23: =IF(D9="x",1,0) -> 0 | E23: =IF(E9="x",D23+1,0) -> 0 | F23: =IF(F9="x",E23+1,0) -> 0 | G23: =IF(G9="x",F23+1,0) -> 0 | H23: =IF(H9="x",G23+1,0) -> 0 | I23: =IF(I9="x",H23+1,0) -> 0 | J23: =IF(J9="x",I23+1,0) -> 0 | K23: =IF(K9="x",J23+1,0) -> 0 | L23: =IF(L9="x",K23+1,0) -> 0 | ... AG23: =IF(AG9="x",AF23+1,0) -> 0
B24: =IF($B10="","",$B10) -> Practicar guitarra 15 minutos | D24: =IF(D10="x",1,0) -> 0 | E24: =IF(E10="x",D24+1,0) -> 0 | F24: =IF(F10="x",E24+1,0) -> 0 | G24: =IF(G10="x",F24+1,0) -> 0 | H24: =IF(H10="x",G24+1,0) -> 0 | I24: =IF(I10="x",H24+1,0) -> 0 | J24: =IF(J10="x",I24+1,0) -> 0 | K24: =IF(K10="x",J24+1,0) -> 0 | L24: =IF(L10="x",K24+1,0) -> 0 | ... AG24: =IF(AG10="x",AF24+1,0) -> 0
B25: =IF($B11="","",$B11) | D25: =IF(D11="x",1,0) -> 0 | E25: =IF(E11="x",D25+1,0) -> 0 | F25: =IF(F11="x",E25+1,0) -> 0 | G25: =IF(G11="x",F25+1,0) -> 0 | H25: =IF(H11="x",G25+1,0) -> 0 | I25: =IF(I11="x",H25+1,0) -> 0 | J25: =IF(J11="x",I25+1,0) -> 0 | K25: =IF(K11="x",J25+1,0) -> 0 | L25: =IF(L11="x",K25+1,0) -> 0 | ... AG25: =IF(AG11="x",AF25+1,0) -> 0
B26: =IF($B12="","",$B12) | D26: =IF(D12="x",1,0) -> 0 | E26: =IF(E12="x",D26+1,0) -> 0 | F26: =IF(F12="x",E26+1,0) -> 0 | G26: =IF(G12="x",F26+1,0) -> 0 | H26: =IF(H12="x",G26+1,0) -> 0 | I26: =IF(I12="x",H26+1,0) -> 0 | J26: =IF(J12="x",I26+1,0) -> 0 | K26: =IF(K12="x",J26+1,0) -> 0 | L26: =IF(L12="x",K26+1,0) -> 0 | ... AG26: =IF(AG12="x",AF26+1,0) -> 0
B27: =IF($B13="","",$B13) | D27: =IF(D13="x",1,0) -> 0 | E27: =IF(E13="x",D27+1,0) -> 0 | F27: =IF(F13="x",E27+1,0) -> 0 | G27: =IF(G13="x",F27+1,0) -> 0 | H27: =IF(H13="x",G27+1,0) -> 0 | I27: =IF(I13="x",H27+1,0) -> 0 | J27: =IF(J13="x",I27+1,0) -> 0 | K27: =IF(K13="x",J27+1,0) -> 0 | L27: =IF(L13="x",K27+1,0) -> 0 | ... AG27: =IF(AG13="x",AF27+1,0) -> 0
B28: =IF($B14="","",$B14) | D28: =IF(D14="x",1,0) -> 0 | E28: =IF(E14="x",D28+1,0) -> 0 | F28: =IF(F14="x",E28+1,0) -> 0 | G28: =IF(G14="x",F28+1,0) -> 0 | H28: =IF(H14="x",G28+1,0) -> 0 | I28: =IF(I14="x",H28+1,0) -> 0 | J28: =IF(J14="x",I28+1,0) -> 0 | K28: =IF(K14="x",J28+1,0) -> 0 | L28: =IF(L14="x",K28+1,0) -> 0 | ... AG28: =IF(AG14="x",AF28+1,0) -> 0
B29: =IF($B15="","",$B15) | D29: =IF(D15="x",1,0) -> 0 | E29: =IF(E15="x",D29+1,0) -> 0 | F29: =IF(F15="x",E29+1,0) -> 0 | G29: =IF(G15="x",F29+1,0) -> 0 | H29: =IF(H15="x",G29+1,0) -> 0 | I29: =IF(I15="x",H29+1,0) -> 0 | J29: =IF(J15="x",I29+1,0) -> 0 | K29: =IF(K15="x",J29+1,0) -> 0 | L29: =IF(L15="x",K29+1,0) -> 0 | ... AG29: =IF(AG15="x",AF29+1,0) -> 0
B30: =IF($B16="","",$B16) | D30: =IF(D16="x",1,0) -> 0 | E30: =IF(E16="x",D30+1,0) -> 0 | F30: =IF(F16="x",E30+1,0) -> 0 | G30: =IF(G16="x",F30+1,0) -> 0 | H30: =IF(H16="x",G30+1,0) -> 0 | I30: =IF(I16="x",H30+1,0) -> 0 | J30: =IF(J16="x",I30+1,0) -> 0 | K30: =IF(K16="x",J30+1,0) -> 0 | L30: =IF(L16="x",K30+1,0) -> 0 | ... AG30: =IF(AG16="x",AF30+1,0) -> 0
B31: =IF($B17="","",$B17) | D31: =IF(D17="x",1,0) -> 0 | E31: =IF(E17="x",D31+1,0) -> 0 | F31: =IF(F17="x",E31+1,0) -> 0 | G31: =IF(G17="x",F31+1,0) -> 0 | H31: =IF(H17="x",G31+1,0) -> 0 | I31: =IF(I17="x",H31+1,0) -> 0 | J31: =IF(J17="x",I31+1,0) -> 0 | K31: =IF(K17="x",J31+1,0) -> 0 | L31: =IF(L17="x",K31+1,0) -> 0 | ... AG31: =IF(AG17="x",AF31+1,0) -> 0
B32: =IF($B18="","",$B18) | D32: =IF(D18="x",1,0) -> 0 | E32: =IF(E18="x",D32+1,0) -> 0 | F32: =IF(F18="x",E32+1,0) -> 0 | G32: =IF(G18="x",F32+1,0) -> 0 | H32: =IF(H18="x",G32+1,0) -> 0 | I32: =IF(I18="x",H32+1,0) -> 0 | J32: =IF(J18="x",I32+1,0) -> 0 | K32: =IF(K18="x",J32+1,0) -> 0 | L32: =IF(L18="x",K32+1,0) -> 0 | ... AG32: =IF(AG18="x",AF32+1,0) -> 0

Sheet Mayo
A1: MAYO 2026
A2: Marca con una X cada día que cumpliste. Todo lo demás se calcula solo.
A3: Jesús González · https://jesus-site-silk.vercel.app/
D5: V | E5: S | F5: D | G5: L | H5: M | I5: M | J5: J | K5: V | L5: S | M5: D | N5: L | O5: M | P5: M | Q5: J | R5: V | S5: S | T5: D | U5: L | V5: M | W5: M | X5: J | Y5: V | Z5: S | AA5: D | AB5: L | AC5: M | AD5: M | AE5: J | AF5: V | AG5: S | AH5: D
B6: Hábito | C6: Meta | D6: 1 | E6: 2 | F6: 3 | G6: 4 | H6: 5 | I6: 6 | J6: 7 | K6: 8 | L6: 9 | M6: 10 | N6: 11 | O6: 12 | P6: 13 | Q6: 14 | R6: 15 | S6: 16 | T6: 17 | U6: 18 | V6: 19 | W6: 20 | X6: 21 | Y6: 22 | Z6: 23 | AA6: 24 | AB6: 25 | AC6: 26 | AD6: 27 | AE6: 28 | AF6: 29 | AG6: 30 | AH6: 31 | AI6: Hechos | AJ6: Meta mes | AK6: % Logro | AL6: Racha máx.
B7: ='Mis Hábitos'!$B$7 -> Leer 10 páginas | C7: =IF('Mis Hábitos'!$B$7="","",'Mis Hábitos'!$F$7) -> 7 | AI7: =IF($B7="","",COUNTIF(D7:AH7,"x")) -> 0 | AJ7: =IF(OR($B7="",$C7=""),"",ROUND($C7*31/7,0)) -> 31 | AK7: =IF(OR($B7="",AJ7="",AJ7=0),"",AI7/AJ7) -> 0 | AL7: =IF($B7="","",MAX(D21:AH21)) -> 0
B8: ='Mis Hábitos'!$B$8 -> Caminar 30 minutos | C8: =IF('Mis Hábitos'!$B$8="","",'Mis Hábitos'!$F$8) -> 5 | AI8: =IF($B8="","",COUNTIF(D8:AH8,"x")) -> 0 | AJ8: =IF(OR($B8="",$C8=""),"",ROUND($C8*31/7,0)) -> 22 | AK8: =IF(OR($B8="",AJ8="",AJ8=0),"",AI8/AJ8) -> 0 | AL8: =IF($B8="","",MAX(D22:AH22)) -> 0
B9: ='Mis Hábitos'!$B$9 -> Revisar pendientes de la semana | C9: =IF('Mis Hábitos'!$B$9="","",'Mis Hábitos'!$F$9) -> 1 | AI9: =IF($B9="","",COUNTIF(D9:AH9,"x")) -> 0 | AJ9: =IF(OR($B9="",$C9=""),"",ROUND($C9*31/7,0)) -> 4 | AK9: =IF(OR($B9="",AJ9="",AJ9=0),"",AI9/AJ9) -> 0 | AL9: =IF($B9="","",MAX(D23:AH23)) -> 0
B10: ='Mis Hábitos'!$B$10 -> Practicar guitarra 15 minutos | C10: =IF('Mis Hábitos'!$B$10="","",'Mis Hábitos'!$F$10) -> 3 | AI10: =IF($B10="","",COUNTIF(D10:AH10,"x")) -> 0 | AJ10: =IF(OR($B10="",$C10=""),"",ROUND($C10*31/7,0)) -> 13 | AK10: =IF(OR($B10="",AJ10="",AJ10=0),"",AI10/AJ10) -> 0 | AL10: =IF($B10="","",MAX(D24:AH24)) -> 0
B11: ='Mis Hábitos'!$B$11 -> 0 | C11: =IF('Mis Hábitos'!$B$11="","",'Mis Hábitos'!$F$11) | AI11: =IF($B11="","",COUNTIF(D11:AH11,"x")) | AJ11: =IF(OR($B11="",$C11=""),"",ROUND($C11*31/7,0)) | AK11: =IF(OR($B11="",AJ11="",AJ11=0),"",AI11/AJ11) | AL11: =IF($B11="","",MAX(D25:AH25))
B12: ='Mis Hábitos'!$B$12 -> 0 | C12: =IF('Mis Hábitos'!$B$12="","",'Mis Hábitos'!$F$12) | AI12: =IF($B12="","",COUNTIF(D12:AH12,"x")) | AJ12: =IF(OR($B12="",$C12=""),"",ROUND($C12*31/7,0)) | AK12: =IF(OR($B12="",AJ12="",AJ12=0),"",AI12/AJ12) | AL12: =IF($B12="","",MAX(D26:AH26))
B13: ='Mis Hábitos'!$B$13 -> 0 | C13: =IF('Mis Hábitos'!$B$13="","",'Mis Hábitos'!$F$13) | AI13: =IF($B13="","",COUNTIF(D13:AH13,"x")) | AJ13: =IF(OR($B13="",$C13=""),"",ROUND($C13*31/7,0)) | AK13: =IF(OR($B13="",AJ13="",AJ13=0),"",AI13/AJ13) | AL13: =IF($B13="","",MAX(D27:AH27))
B14: ='Mis Hábitos'!$B$14 -> 0 | C14: =IF('Mis Hábitos'!$B$14="","",'Mis Hábitos'!$F$14) | AI14: =IF($B14="","",COUNTIF(D14:AH14,"x")) | AJ14: =IF(OR($B14="",$C14=""),"",ROUND($C14*31/7,0)) | AK14: =IF(OR($B14="",AJ14="",AJ14=0),"",AI14/AJ14) | AL14: =IF($B14="","",MAX(D28:AH28))
B15: ='Mis Hábitos'!$B$15 -> 0 | C15: =IF('Mis Hábitos'!$B$15="","",'Mis Hábitos'!$F$15) | AI15: =IF($B15="","",COUNTIF(D15:AH15,"x")) | AJ15: =IF(OR($B15="",$C15=""),"",ROUND($C15*31/7,0)) | AK15: =IF(OR($B15="",AJ15="",AJ15=0),"",AI15/AJ15) | AL15: =IF($B15="","",MAX(D29:AH29))
B16: ='Mis Hábitos'!$B$16 -> 0 | C16: =IF('Mis Hábitos'!$B$16="","",'Mis Hábitos'!$F$16) | AI16: =IF($B16="","",COUNTIF(D16:AH16,"x")) | AJ16: =IF(OR($B16="",$C16=""),"",ROUND($C16*31/7,0)) | AK16: =IF(OR($B16="",AJ16="",AJ16=0),"",AI16/AJ16) | AL16: =IF($B16="","",MAX(D30:AH30))
B17: ='Mis Hábitos'!$B$17 -> 0 | C17: =IF('Mis Hábitos'!$B$17="","",'Mis Hábitos'!$F$17) | AI17: =IF($B17="","",COUNTIF(D17:AH17,"x")) | AJ17: =IF(OR($B17="",$C17=""),"",ROUND($C17*31/7,0)) | AK17: =IF(OR($B17="",AJ17="",AJ17=0),"",AI17/AJ17) | AL17: =IF($B17="","",MAX(D31:AH31))
B18: ='Mis Hábitos'!$B$18 -> 0 | C18: =IF('Mis Hábitos'!$B$18="","",'Mis Hábitos'!$F$18) | AI18: =IF($B18="","",COUNTIF(D18:AH18,"x")) | AJ18: =IF(OR($B18="",$C18=""),"",ROUND($C18*31/7,0)) | AK18: =IF(OR($B18="",AJ18="",AJ18=0),"",AI18/AJ18) | AL18: =IF($B18="","",MAX(D32:AH32))
B19: Cumplidos del día | D19: =COUNTIF(D7:D18,"x") -> 0 | E19: =COUNTIF(E7:E18,"x") -> 0 | F19: =COUNTIF(F7:F18,"x") -> 0 | G19: =COUNTIF(G7:G18,"x") -> 0 | H19: =COUNTIF(H7:H18,"x") -> 0 | I19: =COUNTIF(I7:I18,"x") -> 0 | J19: =COUNTIF(J7:J18,"x") -> 0 | K19: =COUNTIF(K7:K18,"x") -> 0 | ... AH19: =COUNTIF(AH7:AH18,"x") -> 0
B20: x = cumplido · - = no aplicaba ese día · vacío = no se cumplió La columna del día de hoy aparece con borde naranja.
B21: =IF($B7="","",$B7) -> Leer 10 páginas | D21: =IF(D7="x",1,0) -> 0 | E21: =IF(E7="x",D21+1,0) -> 0 | F21: =IF(F7="x",E21+1,0) -> 0 | G21: =IF(G7="x",F21+1,0) -> 0 | H21: =IF(H7="x",G21+1,0) -> 0 | I21: =IF(I7="x",H21+1,0) -> 0 | J21: =IF(J7="x",I21+1,0) -> 0 | K21: =IF(K7="x",J21+1,0) -> 0 | L21: =IF(L7="x",K21+1,0) -> 0 | ... AH21: =IF(AH7="x",AG21+1,0) -> 0
B22: =IF($B8="","",$B8) -> Caminar 30 minutos | D22: =IF(D8="x",1,0) -> 0 | E22: =IF(E8="x",D22+1,0) -> 0 | F22: =IF(F8="x",E22+1,0) -> 0 | G22: =IF(G8="x",F22+1,0) -> 0 | H22: =IF(H8="x",G22+1,0) -> 0 | I22: =IF(I8="x",H22+1,0) -> 0 | J22: =IF(J8="x",I22+1,0) -> 0 | K22: =IF(K8="x",J22+1,0) -> 0 | L22: =IF(L8="x",K22+1,0) -> 0 | ... AH22: =IF(AH8="x",AG22+1,0) -> 0
B23: =IF($B9="","",$B9) -> Revisar pendientes de la semana | D23: =IF(D9="x",1,0) -> 0 | E23: =IF(E9="x",D23+1,0) -> 0 | F23: =IF(F9="x",E23+1,0) -> 0 | G23: =IF(G9="x",F23+1,0) -> 0 | H23: =IF(H9="x",G23+1,0) -> 0 | I23: =IF(I9="x",H23+1,0) -> 0 | J23: =IF(J9="x",I23+1,0) -> 0 | K23: =IF(K9="x",J23+1,0) -> 0 | L23: =IF(L9="x",K23+1,0) -> 0 | ... AH23: =IF(AH9="x",AG23+1,0) -> 0
B24: =IF($B10="","",$B10) -> Practicar guitarra 15 minutos | D24: =IF(D10="x",1,0) -> 0 | E24: =IF(E10="x",D24+1,0) -> 0 | F24: =IF(F10="x",E24+1,0) -> 0 | G24: =IF(G10="x",F24+1,0) -> 0 | H24: =IF(H10="x",G24+1,0) -> 0 | I24: =IF(I10="x",H24+1,0) -> 0 | J24: =IF(J10="x",I24+1,0) -> 0 | K24: =IF(K10="x",J24+1,0) -> 0 | L24: =IF(L10="x",K24+1,0) -> 0 | ... AH24: =IF(AH10="x",AG24+1,0) -> 0
B25: =IF($B11="","",$B11) | D25: =IF(D11="x",1,0) -> 0 | E25: =IF(E11="x",D25+1,0) -> 0 | F25: =IF(F11="x",E25+1,0) -> 0 | G25: =IF(G11="x",F25+1,0) -> 0 | H25: =IF(H11="x",G25+1,0) -> 0 | I25: =IF(I11="x",H25+1,0) -> 0 | J25: =IF(J11="x",I25+1,0) -> 0 | K25: =IF(K11="x",J25+1,0) -> 0 | L25: =IF(L11="x",K25+1,0) -> 0 | ... AH25: =IF(AH11="x",AG25+1,0) -> 0
B26: =IF($B12="","",$B12) | D26: =IF(D12="x",1,0) -> 0 | E26: =IF(E12="x",D26+1,0) -> 0 | F26: =IF(F12="x",E26+1,0) -> 0 | G26: =IF(G12="x",F26+1,0) -> 0 | H26: =IF(H12="x",G26+1,0) -> 0 | I26: =IF(I12="x",H26+1,0) -> 0 | J26: =IF(J12="x",I26+1,0) -> 0 | K26: =IF(K12="x",J26+1,0) -> 0 | L26: =IF(L12="x",K26+1,0) -> 0 | ... AH26: =IF(AH12="x",AG26+1,0) -> 0
B27: =IF($B13="","",$B13) | D27: =IF(D13="x",1,0) -> 0 | E27: =IF(E13="x",D27+1,0) -> 0 | F27: =IF(F13="x",E27+1,0) -> 0 | G27: =IF(G13="x",F27+1,0) -> 0 | H27: =IF(H13="x",G27+1,0) -> 0 | I27: =IF(I13="x",H27+1,0) -> 0 | J27: =IF(J13="x",I27+1,0) -> 0 | K27: =IF(K13="x",J27+1,0) -> 0 | L27: =IF(L13="x",K27+1,0) -> 0 | ... AH27: =IF(AH13="x",AG27+1,0) -> 0
B28: =IF($B14="","",$B14) | D28: =IF(D14="x",1,0) -> 0 | E28: =IF(E14="x",D28+1,0) -> 0 | F28: =IF(F14="x",E28+1,0) -> 0 | G28: =IF(G14="x",F28+1,0) -> 0 | H28: =IF(H14="x",G28+1,0) -> 0 | I28: =IF(I14="x",H28+1,0) -> 0 | J28: =IF(J14="x",I28+1,0) -> 0 | K28: =IF(K14="x",J28+1,0) -> 0 | L28: =IF(L14="x",K28+1,0) -> 0 | ... AH28: =IF(AH14="x",AG28+1,0) -> 0
B29: =IF($B15="","",$B15) | D29: =IF(D15="x",1,0) -> 0 | E29: =IF(E15="x",D29+1,0) -> 0 | F29: =IF(F15="x",E29+1,0) -> 0 | G29: =IF(G15="x",F29+1,0) -> 0 | H29: =IF(H15="x",G29+1,0) -> 0 | I29: =IF(I15="x",H29+1,0) -> 0 | J29: =IF(J15="x",I29+1,0) -> 0 | K29: =IF(K15="x",J29+1,0) -> 0 | L29: =IF(L15="x",K29+1,0) -> 0 | ... AH29: =IF(AH15="x",AG29+1,0) -> 0
B30: =IF($B16="","",$B16) | D30: =IF(D16="x",1,0) -> 0 | E30: =IF(E16="x",D30+1,0) -> 0 | F30: =IF(F16="x",E30+1,0) -> 0 | G30: =IF(G16="x",F30+1,0) -> 0 | H30: =IF(H16="x",G30+1,0) -> 0 | I30: =IF(I16="x",H30+1,0) -> 0 | J30: =IF(J16="x",I30+1,0) -> 0 | K30: =IF(K16="x",J30+1,0) -> 0 | L30: =IF(L16="x",K30+1,0) -> 0 | ... AH30: =IF(AH16="x",AG30+1,0) -> 0
B31: =IF($B17="","",$B17) | D31: =IF(D17="x",1,0) -> 0 | E31: =IF(E17="x",D31+1,0) -> 0 | F31: =IF(F17="x",E31+1,0) -> 0 | G31: =IF(G17="x",F31+1,0) -> 0 | H31: =IF(H17="x",G31+1,0) -> 0 | I31: =IF(I17="x",H31+1,0) -> 0 | J31: =IF(J17="x",I31+1,0) -> 0 | K31: =IF(K17="x",J31+1,0) -> 0 | L31: =IF(L17="x",K31+1,0) -> 0 | ... AH31: =IF(AH17="x",AG31+1,0) -> 0
B32: =IF($B18="","",$B18) | D32: =IF(D18="x",1,0) -> 0 | E32: =IF(E18="x",D32+1,0) -> 0 | F32: =IF(F18="x",E32+1,0) -> 0 | G32: =IF(G18="x",F32+1,0) -> 0 | H32: =IF(H18="x",G32+1,0) -> 0 | I32: =IF(I18="x",H32+1,0) -> 0 | J32: =IF(J18="x",I32+1,0) -> 0 | K32: =IF(K18="x",J32+1,0) -> 0 | L32: =IF(L18="x",K32+1,0) -> 0 | ... AH32: =IF(AH18="x",AG32+1,0) -> 0

Sheet Junio
A1: JUNIO 2026
A2: Marca con una X cada día que cumpliste. Todo lo demás se calcula solo.
A3: Jesús González · https://jesus-site-silk.vercel.app/
D5: L | E5: M | F5: M | G5: J | H5: V | I5: S | J5: D | K5: L | L5: M | M5: M | N5: J | O5: V | P5: S | Q5: D | R5: L | S5: M | T5: M | U5: J | V5: V | W5: S | X5: D | Y5: L | Z5: M | AA5: M | AB5: J | AC5: V | AD5: S | AE5: D | AF5: L | AG5: M
B6: Hábito | C6: Meta | D6: 1 | E6: 2 | F6: 3 | G6: 4 | H6: 5 | I6: 6 | J6: 7 | K6: 8 | L6: 9 | M6: 10 | N6: 11 | O6: 12 | P6: 13 | Q6: 14 | R6: 15 | S6: 16 | T6: 17 | U6: 18 | V6: 19 | W6: 20 | X6: 21 | Y6: 22 | Z6: 23 | AA6: 24 | AB6: 25 | AC6: 26 | AD6: 27 | AE6: 28 | AF6: 29 | AG6: 30 | AH6: Hechos | AI6: Meta mes | AJ6: % Logro | AK6: Racha máx.
B7: ='Mis Hábitos'!$B$7 -> Leer 10 páginas | C7: =IF('Mis Hábitos'!$B$7="","",'Mis Hábitos'!$F$7) -> 7 | AH7: =IF($B7="","",COUNTIF(D7:AG7,"x")) -> 0 | AI7: =IF(OR($B7="",$C7=""),"",ROUND($C7*30/7,0)) -> 30 | AJ7: =IF(OR($B7="",AI7="",AI7=0),"",AH7/AI7) -> 0 | AK7: =IF($B7="","",MAX(D21:AG21)) -> 0
B8: ='Mis Hábitos'!$B$8 -> Caminar 30 minutos | C8: =IF('Mis Hábitos'!$B$8="","",'Mis Hábitos'!$F$8) -> 5 | AH8: =IF($B8="","",COUNTIF(D8:AG8,"x")) -> 0 | AI8: =IF(OR($B8="",$C8=""),"",ROUND($C8*30/7,0)) -> 21 | AJ8: =IF(OR($B8="",AI8="",AI8=0),"",AH8/AI8) -> 0 | AK8: =IF($B8="","",MAX(D22:AG22)) -> 0
B9: ='Mis Hábitos'!$B$9 -> Revisar pendientes de la semana | C9: =IF('Mis Hábitos'!$B$9="","",'Mis Hábitos'!$F$9) -> 1 | AH9: =IF($B9="","",COUNTIF(D9:AG9,"x")) -> 0 | AI9: =IF(OR($B9="",$C9=""),"",ROUND($C9*30/7,0)) -> 4 | AJ9: =IF(OR($B9="",AI9="",AI9=0),"",AH9/AI9) -> 0 | AK9: =IF($B9="","",MAX(D23:AG23)) -> 0
B10: ='Mis Hábitos'!$B$10 -> Practicar guitarra 15 minutos | C10: =IF('Mis Hábitos'!$B$10="","",'Mis Hábitos'!$F$10) -> 3 | AH10: =IF($B10="","",COUNTIF(D10:AG10,"x")) -> 0 | AI10: =IF(OR($B10="",$C10=""),"",ROUND($C10*30/7,0)) -> 13 | AJ10: =IF(OR($B10="",AI10="",AI10=0),"",AH10/AI10) -> 0 | AK10: =IF($B10="","",MAX(D24:AG24)) -> 0
B11: ='Mis Hábitos'!$B$11 -> 0 | C11: =IF('Mis Hábitos'!$B$11="","",'Mis Hábitos'!$F$11) | AH11: =IF($B11="","",COUNTIF(D11:AG11,"x")) | AI11: =IF(OR($B11="",$C11=""),"",ROUND($C11*30/7,0)) | AJ11: =IF(OR($B11="",AI11="",AI11=0),"",AH11/AI11) | AK11: =IF($B11="","",MAX(D25:AG25))
B12: ='Mis Hábitos'!$B$12 -> 0 | C12: =IF('Mis Hábitos'!$B$12="","",'Mis Hábitos'!$F$12) | AH12: =IF($B12="","",COUNTIF(D12:AG12,"x")) | AI12: =IF(OR($B12="",$C12=""),"",ROUND($C12*30/7,0)) | AJ12: =IF(OR($B12="",AI12="",AI12=0),"",AH12/AI12) | AK12: =IF($B12="","",MAX(D26:AG26))
B13: ='Mis Hábitos'!$B$13 -> 0 | C13: =IF('Mis Hábitos'!$B$13="","",'Mis Hábitos'!$F$13) | AH13: =IF($B13="","",COUNTIF(D13:AG13,"x")) | AI13: =IF(OR($B13="",$C13=""),"",ROUND($C13*30/7,0)) | AJ13: =IF(OR($B13="",AI13="",AI13=0),"",AH13/AI13) | AK13: =IF($B13="","",MAX(D27:AG27))
B14: ='Mis Hábitos'!$B$14 -> 0 | C14: =IF('Mis Hábitos'!$B$14="","",'Mis Hábitos'!$F$14) | AH14: =IF($B14="","",COUNTIF(D14:AG14,"x")) | AI14: =IF(OR($B14="",$C14=""),"",ROUND($C14*30/7,0)) | AJ14: =IF(OR($B14="",AI14="",AI14=0),"",AH14/AI14) | AK14: =IF($B14="","",MAX(D28:AG28))
B15: ='Mis Hábitos'!$B$15 -> 0 | C15: =IF('Mis Hábitos'!$B$15="","",'Mis Hábitos'!$F$15) | AH15: =IF($B15="","",COUNTIF(D15:AG15,"x")) | AI15: =IF(OR($B15="",$C15=""),"",ROUND($C15*30/7,0)) | AJ15: =IF(OR($B15="",AI15="",AI15=0),"",AH15/AI15) | AK15: =IF($B15="","",MAX(D29:AG29))
B16: ='Mis Hábitos'!$B$16 -> 0 | C16: =IF('Mis Hábitos'!$B$16="","",'Mis Hábitos'!$F$16) | AH16: =IF($B16="","",COUNTIF(D16:AG16,"x")) | AI16: =IF(OR($B16="",$C16=""),"",ROUND($C16*30/7,0)) | AJ16: =IF(OR($B16="",AI16="",AI16=0),"",AH16/AI16) | AK16: =IF($B16="","",MAX(D30:AG30))
B17: ='Mis Hábitos'!$B$17 -> 0 | C17: =IF('Mis Hábitos'!$B$17="","",'Mis Hábitos'!$F$17) | AH17: =IF($B17="","",COUNTIF(D17:AG17,"x")) | AI17: =IF(OR($B17="",$C17=""),"",ROUND($C17*30/7,0)) | AJ17: =IF(OR($B17="",AI17="",AI17=0),"",AH17/AI17) | AK17: =IF($B17="","",MAX(D31:AG31))
B18: ='Mis Hábitos'!$B$18 -> 0 | C18: =IF('Mis Hábitos'!$B$18="","",'Mis Hábitos'!$F$18) | AH18: =IF($B18="","",COUNTIF(D18:AG18,"x")) | AI18: =IF(OR($B18="",$C18=""),"",ROUND($C18*30/7,0)) | AJ18: =IF(OR($B18="",AI18="",AI18=0),"",AH18/AI18) | AK18: =IF($B18="","",MAX(D32:AG32))
